<?xml version="1.0" encoding="UTF-8"?>
<testng-results ignored="0" total="63" passed="39" failed="16" skipped="8">
  <reporter-output>
  </reporter-output>
  <suite started-at="2022-08-02T14:00:33Z" name="Suite" finished-at="2022-08-02T14:03:49Z" duration-ms="195389">
    <groups>
    </groups>
    <test started-at="2022-08-02T14:00:33Z" name="Test" finished-at="2022-08-02T14:03:49Z" duration-ms="195389">
      <class name="com.tests.LoginPageTest">
        <test-method is-config="true" signature="setUp()[pri:0, instance:com.tests.LoginPageTest@1a20270e]" started-at="2022-08-02T14:00:34Z" name="setUp" finished-at="2022-08-02T14:00:36Z" duration-ms="2804" status="PASS">
          <reporter-output>
          </reporter-output>
        </test-method> <!-- setUp -->
        <test-method signature="TC001_verify_Logo_Is_Displayed()[pri:0, instance:com.tests.LoginPageTest@1a20270e]" started-at="2022-08-02T14:00:36Z" name="TC001_verify_Logo_Is_Displayed" finished-at="2022-08-02T14:00:37Z" duration-ms="77" status="PASS">
          <reporter-output>
          </reporter-output>
        </test-method> <!-- TC001_verify_Logo_Is_Displayed -->
        <test-method signature="TC002_verify_Valid_Heading_On_Loginpage()[pri:0, instance:com.tests.LoginPageTest@1a20270e]" started-at="2022-08-02T14:00:37Z" name="TC002_verify_Valid_Heading_On_Loginpage" finished-at="2022-08-02T14:00:37Z" duration-ms="31" status="PASS">
          <reporter-output>
          </reporter-output>
        </test-method> <!-- TC002_verify_Valid_Heading_On_Loginpage -->
        <test-method signature="TC003_verify_Valid_CourseName_On_Loginpage()[pri:0, instance:com.tests.LoginPageTest@1a20270e]" started-at="2022-08-02T14:00:37Z" name="TC003_verify_Valid_CourseName_On_Loginpage" finished-at="2022-08-02T14:00:37Z" duration-ms="26" status="PASS">
          <reporter-output>
          </reporter-output>
        </test-method> <!-- TC003_verify_Valid_CourseName_On_Loginpage -->
        <test-method signature="TC004_verify_Email_Error_Message()[pri:0, instance:com.tests.LoginPageTest@1a20270e]" started-at="2022-08-02T14:00:37Z" name="TC004_verify_Email_Error_Message" finished-at="2022-08-02T14:00:37Z" duration-ms="397" status="PASS">
          <reporter-output>
          </reporter-output>
        </test-method> <!-- TC004_verify_Email_Error_Message -->
        <test-method signature="TC005_verify_Password_Error_Message()[pri:0, instance:com.tests.LoginPageTest@1a20270e]" started-at="2022-08-02T14:00:37Z" name="TC005_verify_Password_Error_Message" finished-at="2022-08-02T14:00:37Z" duration-ms="400" status="PASS">
          <reporter-output>
          </reporter-output>
        </test-method> <!-- TC005_verify_Password_Error_Message -->
        <test-method signature="TC006_verify_Enter_Invalid_Email_Error_Message()[pri:0, instance:com.tests.LoginPageTest@1a20270e]" started-at="2022-08-02T14:00:37Z" name="TC006_verify_Enter_Invalid_Email_Error_Message" finished-at="2022-08-02T14:00:38Z" duration-ms="421" status="PASS">
          <reporter-output>
          </reporter-output>
        </test-method> <!-- TC006_verify_Enter_Invalid_Email_Error_Message -->
        <test-method signature="TC007_verify_Enter_Invalid_Password_Error_Message()[pri:0, instance:com.tests.LoginPageTest@1a20270e]" started-at="2022-08-02T14:00:38Z" name="TC007_verify_Enter_Invalid_Password_Error_Message" finished-at="2022-08-02T14:00:38Z" duration-ms="413" status="PASS">
          <reporter-output>
          </reporter-output>
        </test-method> <!-- TC007_verify_Enter_Invalid_Password_Error_Message -->
        <test-method signature="TC008_verify_Register_Link_Is_Clickable()[pri:0, instance:com.tests.LoginPageTest@1a20270e]" started-at="2022-08-02T14:00:38Z" name="TC008_verify_Register_Link_Is_Clickable" finished-at="2022-08-02T14:00:38Z" duration-ms="233" status="PASS">
          <reporter-output>
          </reporter-output>
        </test-method> <!-- TC008_verify_Register_Link_Is_Clickable -->
        <test-method signature="TC009_verify_Valid_Login_Credential_Scenario(java.lang.String, java.lang.String)[pri:0, instance:com.tests.LoginPageTest@1a20270e]" started-at="2022-08-02T14:00:39Z" name="TC009_verify_Valid_Login_Credential_Scenario" data-provider="setData" finished-at="2022-08-02T14:00:39Z" duration-ms="338" status="SKIP">
          <params>
            <param index="0">
              <value>
                <![CDATA[ram@gmail.com]]>
              </value>
            </param>
            <param index="1">
              <value>
                <![CDATA[987456]]>
              </value>
            </param>
          </params>
          <exception class="java.lang.AssertionError">
            <message>
              <![CDATA[expected [true] but found [false]]]>
            </message>
            <full-stacktrace>
              <![CDATA[java.lang.AssertionError: expected [true] but found [false]
at org.testng.Assert.fail(Assert.java:96)
at org.testng.Assert.failNotEquals(Assert.java:776)
at org.testng.Assert.assertTrue(Assert.java:44)
at org.testng.Assert.assertTrue(Assert.java:54)
at com.tests.LoginPageTest.TC009_verify_Valid_Login_Credential_Scenario(LoginPageTest.java:93)
at java.base/jdk.internal.reflect.NativeMethodAccessorImpl.invoke0(Native Method)
at java.base/jdk.internal.reflect.NativeMethodAccessorImpl.invoke(NativeMethodAccessorImpl.java:62)
at java.base/jdk.internal.reflect.DelegatingMethodAccessorImpl.invoke(DelegatingMethodAccessorImpl.java:43)
at java.base/java.lang.reflect.Method.invoke(Method.java:566)
at org.testng.internal.MethodInvocationHelper.invokeMethod(MethodInvocationHelper.java:124)
at org.testng.internal.Invoker.invokeMethod(Invoker.java:583)
at org.testng.internal.Invoker.invokeTestMethod(Invoker.java:719)
at org.testng.internal.Invoker.invokeTestMethods(Invoker.java:989)
at org.testng.internal.TestMethodWorker.invokeTestMethods(TestMethodWorker.java:125)
at org.testng.internal.TestMethodWorker.run(TestMethodWorker.java:109)
at org.testng.TestRunner.privateRun(TestRunner.java:648)
at org.testng.TestRunner.run(TestRunner.java:505)
at org.testng.SuiteRunner.runTest(SuiteRunner.java:455)
at org.testng.SuiteRunner.runSequentially(SuiteRunner.java:450)
at org.testng.SuiteRunner.privateRun(SuiteRunner.java:415)
at org.testng.SuiteRunner.run(SuiteRunner.java:364)
at org.testng.SuiteRunnerWorker.runSuite(SuiteRunnerWorker.java:52)
at org.testng.SuiteRunnerWorker.run(SuiteRunnerWorker.java:84)
at org.testng.TestNG.runSuitesSequentially(TestNG.java:1208)
at org.testng.TestNG.runSuitesLocally(TestNG.java:1137)
at org.testng.TestNG.runSuites(TestNG.java:1049)
at org.testng.TestNG.run(TestNG.java:1017)
at org.testng.remote.AbstractRemoteTestNG.run(AbstractRemoteTestNG.java:115)
at org.testng.remote.RemoteTestNG.initAndRun(RemoteTestNG.java:251)
at org.testng.remote.RemoteTestNG.main(RemoteTestNG.java:77)
]]>
            </full-stacktrace>
          </exception> <!-- java.lang.AssertionError -->
          <reporter-output>
          </reporter-output>
        </test-method> <!-- TC009_verify_Valid_Login_Credential_Scenario -->
        <test-method signature="TC009_verify_Valid_Login_Credential_Scenario(java.lang.String, java.lang.String)[pri:0, instance:com.tests.LoginPageTest@1a20270e]" started-at="2022-08-02T14:00:39Z" name="TC009_verify_Valid_Login_Credential_Scenario" data-provider="setData" finished-at="2022-08-02T14:00:40Z" duration-ms="306" status="SKIP">
          <params>
            <param index="0">
              <value>
                <![CDATA[ram@gmail.com]]>
              </value>
            </param>
            <param index="1">
              <value>
                <![CDATA[987456]]>
              </value>
            </param>
          </params>
          <exception class="java.lang.AssertionError">
            <message>
              <![CDATA[expected [true] but found [false]]]>
            </message>
            <full-stacktrace>
              <![CDATA[java.lang.AssertionError: expected [true] but found [false]
at org.testng.Assert.fail(Assert.java:96)
at org.testng.Assert.failNotEquals(Assert.java:776)
at org.testng.Assert.assertTrue(Assert.java:44)
at org.testng.Assert.assertTrue(Assert.java:54)
at com.tests.LoginPageTest.TC009_verify_Valid_Login_Credential_Scenario(LoginPageTest.java:93)
at java.base/jdk.internal.reflect.NativeMethodAccessorImpl.invoke0(Native Method)
at java.base/jdk.internal.reflect.NativeMethodAccessorImpl.invoke(NativeMethodAccessorImpl.java:62)
at java.base/jdk.internal.reflect.DelegatingMethodAccessorImpl.invoke(DelegatingMethodAccessorImpl.java:43)
at java.base/java.lang.reflect.Method.invoke(Method.java:566)
at org.testng.internal.MethodInvocationHelper.invokeMethod(MethodInvocationHelper.java:124)
at org.testng.internal.Invoker.invokeMethod(Invoker.java:583)
at org.testng.internal.Invoker.retryFailed(Invoker.java:839)
at org.testng.internal.Invoker.invokeTestMethods(Invoker.java:1010)
at org.testng.internal.TestMethodWorker.invokeTestMethods(TestMethodWorker.java:125)
at org.testng.internal.TestMethodWorker.run(TestMethodWorker.java:109)
at org.testng.TestRunner.privateRun(TestRunner.java:648)
at org.testng.TestRunner.run(TestRunner.java:505)
at org.testng.SuiteRunner.runTest(SuiteRunner.java:455)
at org.testng.SuiteRunner.runSequentially(SuiteRunner.java:450)
at org.testng.SuiteRunner.privateRun(SuiteRunner.java:415)
at org.testng.SuiteRunner.run(SuiteRunner.java:364)
at org.testng.SuiteRunnerWorker.runSuite(SuiteRunnerWorker.java:52)
at org.testng.SuiteRunnerWorker.run(SuiteRunnerWorker.java:84)
at org.testng.TestNG.runSuitesSequentially(TestNG.java:1208)
at org.testng.TestNG.runSuitesLocally(TestNG.java:1137)
at org.testng.TestNG.runSuites(TestNG.java:1049)
at org.testng.TestNG.run(TestNG.java:1017)
at org.testng.remote.AbstractRemoteTestNG.run(AbstractRemoteTestNG.java:115)
at org.testng.remote.RemoteTestNG.initAndRun(RemoteTestNG.java:251)
at org.testng.remote.RemoteTestNG.main(RemoteTestNG.java:77)
]]>
            </full-stacktrace>
          </exception> <!-- java.lang.AssertionError -->
          <reporter-output>
          </reporter-output>
        </test-method> <!-- TC009_verify_Valid_Login_Credential_Scenario -->
        <test-method signature="TC009_verify_Valid_Login_Credential_Scenario(java.lang.String, java.lang.String)[pri:0, instance:com.tests.LoginPageTest@1a20270e]" started-at="2022-08-02T14:00:40Z" name="TC009_verify_Valid_Login_Credential_Scenario" data-provider="setData" finished-at="2022-08-02T14:00:40Z" duration-ms="274" status="FAIL">
          <params>
            <param index="0">
              <value>
                <![CDATA[ram@gmail.com]]>
              </value>
            </param>
            <param index="1">
              <value>
                <![CDATA[987456]]>
              </value>
            </param>
          </params>
          <exception class="java.lang.AssertionError">
            <message>
              <![CDATA[expected [true] but found [false]]]>
            </message>
            <full-stacktrace>
              <![CDATA[java.lang.AssertionError: expected [true] but found [false]
at org.testng.Assert.fail(Assert.java:96)
at org.testng.Assert.failNotEquals(Assert.java:776)
at org.testng.Assert.assertTrue(Assert.java:44)
at org.testng.Assert.assertTrue(Assert.java:54)
at com.tests.LoginPageTest.TC009_verify_Valid_Login_Credential_Scenario(LoginPageTest.java:93)
at java.base/jdk.internal.reflect.NativeMethodAccessorImpl.invoke0(Native Method)
at java.base/jdk.internal.reflect.NativeMethodAccessorImpl.invoke(NativeMethodAccessorImpl.java:62)
at java.base/jdk.internal.reflect.DelegatingMethodAccessorImpl.invoke(DelegatingMethodAccessorImpl.java:43)
at java.base/java.lang.reflect.Method.invoke(Method.java:566)
at org.testng.internal.MethodInvocationHelper.invokeMethod(MethodInvocationHelper.java:124)
at org.testng.internal.Invoker.invokeMethod(Invoker.java:583)
at org.testng.internal.Invoker.retryFailed(Invoker.java:839)
at org.testng.internal.Invoker.invokeTestMethods(Invoker.java:1010)
at org.testng.internal.TestMethodWorker.invokeTestMethods(TestMethodWorker.java:125)
at org.testng.internal.TestMethodWorker.run(TestMethodWorker.java:109)
at org.testng.TestRunner.privateRun(TestRunner.java:648)
at org.testng.TestRunner.run(TestRunner.java:505)
at org.testng.SuiteRunner.runTest(SuiteRunner.java:455)
at org.testng.SuiteRunner.runSequentially(SuiteRunner.java:450)
at org.testng.SuiteRunner.privateRun(SuiteRunner.java:415)
at org.testng.SuiteRunner.run(SuiteRunner.java:364)
at org.testng.SuiteRunnerWorker.runSuite(SuiteRunnerWorker.java:52)
at org.testng.SuiteRunnerWorker.run(SuiteRunnerWorker.java:84)
at org.testng.TestNG.runSuitesSequentially(TestNG.java:1208)
at org.testng.TestNG.runSuitesLocally(TestNG.java:1137)
at org.testng.TestNG.runSuites(TestNG.java:1049)
at org.testng.TestNG.run(TestNG.java:1017)
at org.testng.remote.AbstractRemoteTestNG.run(AbstractRemoteTestNG.java:115)
at org.testng.remote.RemoteTestNG.initAndRun(RemoteTestNG.java:251)
at org.testng.remote.RemoteTestNG.main(RemoteTestNG.java:77)
]]>
            </full-stacktrace>
          </exception> <!-- java.lang.AssertionError -->
          <reporter-output>
          </reporter-output>
        </test-method> <!-- TC009_verify_Valid_Login_Credential_Scenario -->
        <test-method signature="TC009_verify_Valid_Login_Credential_Scenario(java.lang.String, java.lang.String)[pri:0, instance:com.tests.LoginPageTest@1a20270e]" started-at="2022-08-02T14:00:40Z" name="TC009_verify_Valid_Login_Credential_Scenario" data-provider="setData" finished-at="2022-08-02T14:00:41Z" duration-ms="302" status="FAIL">
          <params>
            <param index="0">
              <value>
                <![CDATA[sham@gmail.com]]>
              </value>
            </param>
            <param index="1">
              <value>
                <![CDATA[654123]]>
              </value>
            </param>
          </params>
          <exception class="java.lang.AssertionError">
            <message>
              <![CDATA[expected [true] but found [false]]]>
            </message>
            <full-stacktrace>
              <![CDATA[java.lang.AssertionError: expected [true] but found [false]
at org.testng.Assert.fail(Assert.java:96)
at org.testng.Assert.failNotEquals(Assert.java:776)
at org.testng.Assert.assertTrue(Assert.java:44)
at org.testng.Assert.assertTrue(Assert.java:54)
at com.tests.LoginPageTest.TC009_verify_Valid_Login_Credential_Scenario(LoginPageTest.java:93)
at java.base/jdk.internal.reflect.NativeMethodAccessorImpl.invoke0(Native Method)
at java.base/jdk.internal.reflect.NativeMethodAccessorImpl.invoke(NativeMethodAccessorImpl.java:62)
at java.base/jdk.internal.reflect.DelegatingMethodAccessorImpl.invoke(DelegatingMethodAccessorImpl.java:43)
at java.base/java.lang.reflect.Method.invoke(Method.java:566)
at org.testng.internal.MethodInvocationHelper.invokeMethod(MethodInvocationHelper.java:124)
at org.testng.internal.Invoker.invokeMethod(Invoker.java:583)
at org.testng.internal.Invoker.invokeTestMethod(Invoker.java:719)
at org.testng.internal.Invoker.invokeTestMethods(Invoker.java:989)
at org.testng.internal.TestMethodWorker.invokeTestMethods(TestMethodWorker.java:125)
at org.testng.internal.TestMethodWorker.run(TestMethodWorker.java:109)
at org.testng.TestRunner.privateRun(TestRunner.java:648)
at org.testng.TestRunner.run(TestRunner.java:505)
at org.testng.SuiteRunner.runTest(SuiteRunner.java:455)
at org.testng.SuiteRunner.runSequentially(SuiteRunner.java:450)
at org.testng.SuiteRunner.privateRun(SuiteRunner.java:415)
at org.testng.SuiteRunner.run(SuiteRunner.java:364)
at org.testng.SuiteRunnerWorker.runSuite(SuiteRunnerWorker.java:52)
at org.testng.SuiteRunnerWorker.run(SuiteRunnerWorker.java:84)
at org.testng.TestNG.runSuitesSequentially(TestNG.java:1208)
at org.testng.TestNG.runSuitesLocally(TestNG.java:1137)
at org.testng.TestNG.runSuites(TestNG.java:1049)
at org.testng.TestNG.run(TestNG.java:1017)
at org.testng.remote.AbstractRemoteTestNG.run(AbstractRemoteTestNG.java:115)
at org.testng.remote.RemoteTestNG.initAndRun(RemoteTestNG.java:251)
at org.testng.remote.RemoteTestNG.main(RemoteTestNG.java:77)
]]>
            </full-stacktrace>
          </exception> <!-- java.lang.AssertionError -->
          <reporter-output>
          </reporter-output>
        </test-method> <!-- TC009_verify_Valid_Login_Credential_Scenario -->
        <test-method signature="TC009_verify_Valid_Login_Credential_Scenario(java.lang.String, java.lang.String)[pri:0, instance:com.tests.LoginPageTest@1a20270e]" started-at="2022-08-02T14:00:41Z" name="TC009_verify_Valid_Login_Credential_Scenario" data-provider="setData" finished-at="2022-08-02T14:00:41Z" duration-ms="312" status="FAIL">
          <params>
            <param index="0">
              <value>
                <![CDATA[sham@gmail.com]]>
              </value>
            </param>
            <param index="1">
              <value>
                <![CDATA[654123]]>
              </value>
            </param>
          </params>
          <exception class="java.lang.AssertionError">
            <message>
              <![CDATA[expected [true] but found [false]]]>
            </message>
            <full-stacktrace>
              <![CDATA[java.lang.AssertionError: expected [true] but found [false]
at org.testng.Assert.fail(Assert.java:96)
at org.testng.Assert.failNotEquals(Assert.java:776)
at org.testng.Assert.assertTrue(Assert.java:44)
at org.testng.Assert.assertTrue(Assert.java:54)
at com.tests.LoginPageTest.TC009_verify_Valid_Login_Credential_Scenario(LoginPageTest.java:93)
at java.base/jdk.internal.reflect.NativeMethodAccessorImpl.invoke0(Native Method)
at java.base/jdk.internal.reflect.NativeMethodAccessorImpl.invoke(NativeMethodAccessorImpl.java:62)
at java.base/jdk.internal.reflect.DelegatingMethodAccessorImpl.invoke(DelegatingMethodAccessorImpl.java:43)
at java.base/java.lang.reflect.Method.invoke(Method.java:566)
at org.testng.internal.MethodInvocationHelper.invokeMethod(MethodInvocationHelper.java:124)
at org.testng.internal.Invoker.invokeMethod(Invoker.java:583)
at org.testng.internal.Invoker.retryFailed(Invoker.java:839)
at org.testng.internal.Invoker.invokeTestMethods(Invoker.java:1010)
at org.testng.internal.TestMethodWorker.invokeTestMethods(TestMethodWorker.java:125)
at org.testng.internal.TestMethodWorker.run(TestMethodWorker.java:109)
at org.testng.TestRunner.privateRun(TestRunner.java:648)
at org.testng.TestRunner.run(TestRunner.java:505)
at org.testng.SuiteRunner.runTest(SuiteRunner.java:455)
at org.testng.SuiteRunner.runSequentially(SuiteRunner.java:450)
at org.testng.SuiteRunner.privateRun(SuiteRunner.java:415)
at org.testng.SuiteRunner.run(SuiteRunner.java:364)
at org.testng.SuiteRunnerWorker.runSuite(SuiteRunnerWorker.java:52)
at org.testng.SuiteRunnerWorker.run(SuiteRunnerWorker.java:84)
at org.testng.TestNG.runSuitesSequentially(TestNG.java:1208)
at org.testng.TestNG.runSuitesLocally(TestNG.java:1137)
at org.testng.TestNG.runSuites(TestNG.java:1049)
at org.testng.TestNG.run(TestNG.java:1017)
at org.testng.remote.AbstractRemoteTestNG.run(AbstractRemoteTestNG.java:115)
at org.testng.remote.RemoteTestNG.initAndRun(RemoteTestNG.java:251)
at org.testng.remote.RemoteTestNG.main(RemoteTestNG.java:77)
]]>
            </full-stacktrace>
          </exception> <!-- java.lang.AssertionError -->
          <reporter-output>
          </reporter-output>
        </test-method> <!-- TC009_verify_Valid_Login_Credential_Scenario -->
        <test-method signature="TC009_verify_Valid_Login_Credential_Scenario(java.lang.String, java.lang.String)[pri:0, instance:com.tests.LoginPageTest@1a20270e]" started-at="2022-08-02T14:00:41Z" name="TC009_verify_Valid_Login_Credential_Scenario" data-provider="setData" finished-at="2022-08-02T14:00:42Z" duration-ms="340" status="FAIL">
          <params>
            <param index="0">
              <value>
                <![CDATA[raj@gmail.com]]>
              </value>
            </param>
            <param index="1">
              <value>
                <![CDATA[654789]]>
              </value>
            </param>
          </params>
          <exception class="java.lang.AssertionError">
            <message>
              <![CDATA[expected [true] but found [false]]]>
            </message>
            <full-stacktrace>
              <![CDATA[java.lang.AssertionError: expected [true] but found [false]
at org.testng.Assert.fail(Assert.java:96)
at org.testng.Assert.failNotEquals(Assert.java:776)
at org.testng.Assert.assertTrue(Assert.java:44)
at org.testng.Assert.assertTrue(Assert.java:54)
at com.tests.LoginPageTest.TC009_verify_Valid_Login_Credential_Scenario(LoginPageTest.java:93)
at java.base/jdk.internal.reflect.NativeMethodAccessorImpl.invoke0(Native Method)
at java.base/jdk.internal.reflect.NativeMethodAccessorImpl.invoke(NativeMethodAccessorImpl.java:62)
at java.base/jdk.internal.reflect.DelegatingMethodAccessorImpl.invoke(DelegatingMethodAccessorImpl.java:43)
at java.base/java.lang.reflect.Method.invoke(Method.java:566)
at org.testng.internal.MethodInvocationHelper.invokeMethod(MethodInvocationHelper.java:124)
at org.testng.internal.Invoker.invokeMethod(Invoker.java:583)
at org.testng.internal.Invoker.invokeTestMethod(Invoker.java:719)
at org.testng.internal.Invoker.invokeTestMethods(Invoker.java:989)
at org.testng.internal.TestMethodWorker.invokeTestMethods(TestMethodWorker.java:125)
at org.testng.internal.TestMethodWorker.run(TestMethodWorker.java:109)
at org.testng.TestRunner.privateRun(TestRunner.java:648)
at org.testng.TestRunner.run(TestRunner.java:505)
at org.testng.SuiteRunner.runTest(SuiteRunner.java:455)
at org.testng.SuiteRunner.runSequentially(SuiteRunner.java:450)
at org.testng.SuiteRunner.privateRun(SuiteRunner.java:415)
at org.testng.SuiteRunner.run(SuiteRunner.java:364)
at org.testng.SuiteRunnerWorker.runSuite(SuiteRunnerWorker.java:52)
at org.testng.SuiteRunnerWorker.run(SuiteRunnerWorker.java:84)
at org.testng.TestNG.runSuitesSequentially(TestNG.java:1208)
at org.testng.TestNG.runSuitesLocally(TestNG.java:1137)
at org.testng.TestNG.runSuites(TestNG.java:1049)
at org.testng.TestNG.run(TestNG.java:1017)
at org.testng.remote.AbstractRemoteTestNG.run(AbstractRemoteTestNG.java:115)
at org.testng.remote.RemoteTestNG.initAndRun(RemoteTestNG.java:251)
at org.testng.remote.RemoteTestNG.main(RemoteTestNG.java:77)
]]>
            </full-stacktrace>
          </exception> <!-- java.lang.AssertionError -->
          <reporter-output>
          </reporter-output>
        </test-method> <!-- TC009_verify_Valid_Login_Credential_Scenario -->
        <test-method signature="TC009_verify_Valid_Login_Credential_Scenario(java.lang.String, java.lang.String)[pri:0, instance:com.tests.LoginPageTest@1a20270e]" started-at="2022-08-02T14:00:42Z" name="TC009_verify_Valid_Login_Credential_Scenario" data-provider="setData" finished-at="2022-08-02T14:00:42Z" duration-ms="354" status="FAIL">
          <params>
            <param index="0">
              <value>
                <![CDATA[raj@gmail.com]]>
              </value>
            </param>
            <param index="1">
              <value>
                <![CDATA[654789]]>
              </value>
            </param>
          </params>
          <exception class="java.lang.AssertionError">
            <message>
              <![CDATA[expected [true] but found [false]]]>
            </message>
            <full-stacktrace>
              <![CDATA[java.lang.AssertionError: expected [true] but found [false]
at org.testng.Assert.fail(Assert.java:96)
at org.testng.Assert.failNotEquals(Assert.java:776)
at org.testng.Assert.assertTrue(Assert.java:44)
at org.testng.Assert.assertTrue(Assert.java:54)
at com.tests.LoginPageTest.TC009_verify_Valid_Login_Credential_Scenario(LoginPageTest.java:93)
at java.base/jdk.internal.reflect.NativeMethodAccessorImpl.invoke0(Native Method)
at java.base/jdk.internal.reflect.NativeMethodAccessorImpl.invoke(NativeMethodAccessorImpl.java:62)
at java.base/jdk.internal.reflect.DelegatingMethodAccessorImpl.invoke(DelegatingMethodAccessorImpl.java:43)
at java.base/java.lang.reflect.Method.invoke(Method.java:566)
at org.testng.internal.MethodInvocationHelper.invokeMethod(MethodInvocationHelper.java:124)
at org.testng.internal.Invoker.invokeMethod(Invoker.java:583)
at org.testng.internal.Invoker.retryFailed(Invoker.java:839)
at org.testng.internal.Invoker.invokeTestMethods(Invoker.java:1010)
at org.testng.internal.TestMethodWorker.invokeTestMethods(TestMethodWorker.java:125)
at org.testng.internal.TestMethodWorker.run(TestMethodWorker.java:109)
at org.testng.TestRunner.privateRun(TestRunner.java:648)
at org.testng.TestRunner.run(TestRunner.java:505)
at org.testng.SuiteRunner.runTest(SuiteRunner.java:455)
at org.testng.SuiteRunner.runSequentially(SuiteRunner.java:450)
at org.testng.SuiteRunner.privateRun(SuiteRunner.java:415)
at org.testng.SuiteRunner.run(SuiteRunner.java:364)
at org.testng.SuiteRunnerWorker.runSuite(SuiteRunnerWorker.java:52)
at org.testng.SuiteRunnerWorker.run(SuiteRunnerWorker.java:84)
at org.testng.TestNG.runSuitesSequentially(TestNG.java:1208)
at org.testng.TestNG.runSuitesLocally(TestNG.java:1137)
at org.testng.TestNG.runSuites(TestNG.java:1049)
at org.testng.TestNG.run(TestNG.java:1017)
at org.testng.remote.AbstractRemoteTestNG.run(AbstractRemoteTestNG.java:115)
at org.testng.remote.RemoteTestNG.initAndRun(RemoteTestNG.java:251)
at org.testng.remote.RemoteTestNG.main(RemoteTestNG.java:77)
]]>
            </full-stacktrace>
          </exception> <!-- java.lang.AssertionError -->
          <reporter-output>
          </reporter-output>
        </test-method> <!-- TC009_verify_Valid_Login_Credential_Scenario -->
        <test-method signature="TC009_verify_Valid_Login_Credential_Scenario(java.lang.String, java.lang.String)[pri:0, instance:com.tests.LoginPageTest@1a20270e]" started-at="2022-08-02T14:00:42Z" name="TC009_verify_Valid_Login_Credential_Scenario" data-provider="setData" finished-at="2022-08-02T14:00:43Z" duration-ms="329" status="FAIL">
          <params>
            <param index="0">
              <value>
                <![CDATA[#&*@*$%@]]>
              </value>
            </param>
            <param index="1">
              <value>
                <![CDATA[&*^%$#$]]>
              </value>
            </param>
          </params>
          <exception class="java.lang.AssertionError">
            <message>
              <![CDATA[expected [true] but found [false]]]>
            </message>
            <full-stacktrace>
              <![CDATA[java.lang.AssertionError: expected [true] but found [false]
at org.testng.Assert.fail(Assert.java:96)
at org.testng.Assert.failNotEquals(Assert.java:776)
at org.testng.Assert.assertTrue(Assert.java:44)
at org.testng.Assert.assertTrue(Assert.java:54)
at com.tests.LoginPageTest.TC009_verify_Valid_Login_Credential_Scenario(LoginPageTest.java:93)
at java.base/jdk.internal.reflect.NativeMethodAccessorImpl.invoke0(Native Method)
at java.base/jdk.internal.reflect.NativeMethodAccessorImpl.invoke(NativeMethodAccessorImpl.java:62)
at java.base/jdk.internal.reflect.DelegatingMethodAccessorImpl.invoke(DelegatingMethodAccessorImpl.java:43)
at java.base/java.lang.reflect.Method.invoke(Method.java:566)
at org.testng.internal.MethodInvocationHelper.invokeMethod(MethodInvocationHelper.java:124)
at org.testng.internal.Invoker.invokeMethod(Invoker.java:583)
at org.testng.internal.Invoker.invokeTestMethod(Invoker.java:719)
at org.testng.internal.Invoker.invokeTestMethods(Invoker.java:989)
at org.testng.internal.TestMethodWorker.invokeTestMethods(TestMethodWorker.java:125)
at org.testng.internal.TestMethodWorker.run(TestMethodWorker.java:109)
at org.testng.TestRunner.privateRun(TestRunner.java:648)
at org.testng.TestRunner.run(TestRunner.java:505)
at org.testng.SuiteRunner.runTest(SuiteRunner.java:455)
at org.testng.SuiteRunner.runSequentially(SuiteRunner.java:450)
at org.testng.SuiteRunner.privateRun(SuiteRunner.java:415)
at org.testng.SuiteRunner.run(SuiteRunner.java:364)
at org.testng.SuiteRunnerWorker.runSuite(SuiteRunnerWorker.java:52)
at org.testng.SuiteRunnerWorker.run(SuiteRunnerWorker.java:84)
at org.testng.TestNG.runSuitesSequentially(TestNG.java:1208)
at org.testng.TestNG.runSuitesLocally(TestNG.java:1137)
at org.testng.TestNG.runSuites(TestNG.java:1049)
at org.testng.TestNG.run(TestNG.java:1017)
at org.testng.remote.AbstractRemoteTestNG.run(AbstractRemoteTestNG.java:115)
at org.testng.remote.RemoteTestNG.initAndRun(RemoteTestNG.java:251)
at org.testng.remote.RemoteTestNG.main(RemoteTestNG.java:77)
]]>
            </full-stacktrace>
          </exception> <!-- java.lang.AssertionError -->
          <reporter-output>
          </reporter-output>
        </test-method> <!-- TC009_verify_Valid_Login_Credential_Scenario -->
        <test-method signature="TC009_verify_Valid_Login_Credential_Scenario(java.lang.String, java.lang.String)[pri:0, instance:com.tests.LoginPageTest@1a20270e]" started-at="2022-08-02T14:00:43Z" name="TC009_verify_Valid_Login_Credential_Scenario" data-provider="setData" finished-at="2022-08-02T14:00:43Z" duration-ms="330" status="FAIL">
          <params>
            <param index="0">
              <value>
                <![CDATA[#&*@*$%@]]>
              </value>
            </param>
            <param index="1">
              <value>
                <![CDATA[&*^%$#$]]>
              </value>
            </param>
          </params>
          <exception class="java.lang.AssertionError">
            <message>
              <![CDATA[expected [true] but found [false]]]>
            </message>
            <full-stacktrace>
              <![CDATA[java.lang.AssertionError: expected [true] but found [false]
at org.testng.Assert.fail(Assert.java:96)
at org.testng.Assert.failNotEquals(Assert.java:776)
at org.testng.Assert.assertTrue(Assert.java:44)
at org.testng.Assert.assertTrue(Assert.java:54)
at com.tests.LoginPageTest.TC009_verify_Valid_Login_Credential_Scenario(LoginPageTest.java:93)
at java.base/jdk.internal.reflect.NativeMethodAccessorImpl.invoke0(Native Method)
at java.base/jdk.internal.reflect.NativeMethodAccessorImpl.invoke(NativeMethodAccessorImpl.java:62)
at java.base/jdk.internal.reflect.DelegatingMethodAccessorImpl.invoke(DelegatingMethodAccessorImpl.java:43)
at java.base/java.lang.reflect.Method.invoke(Method.java:566)
at org.testng.internal.MethodInvocationHelper.invokeMethod(MethodInvocationHelper.java:124)
at org.testng.internal.Invoker.invokeMethod(Invoker.java:583)
at org.testng.internal.Invoker.retryFailed(Invoker.java:839)
at org.testng.internal.Invoker.invokeTestMethods(Invoker.java:1010)
at org.testng.internal.TestMethodWorker.invokeTestMethods(TestMethodWorker.java:125)
at org.testng.internal.TestMethodWorker.run(TestMethodWorker.java:109)
at org.testng.TestRunner.privateRun(TestRunner.java:648)
at org.testng.TestRunner.run(TestRunner.java:505)
at org.testng.SuiteRunner.runTest(SuiteRunner.java:455)
at org.testng.SuiteRunner.runSequentially(SuiteRunner.java:450)
at org.testng.SuiteRunner.privateRun(SuiteRunner.java:415)
at org.testng.SuiteRunner.run(SuiteRunner.java:364)
at org.testng.SuiteRunnerWorker.runSuite(SuiteRunnerWorker.java:52)
at org.testng.SuiteRunnerWorker.run(SuiteRunnerWorker.java:84)
at org.testng.TestNG.runSuitesSequentially(TestNG.java:1208)
at org.testng.TestNG.runSuitesLocally(TestNG.java:1137)
at org.testng.TestNG.runSuites(TestNG.java:1049)
at org.testng.TestNG.run(TestNG.java:1017)
at org.testng.remote.AbstractRemoteTestNG.run(AbstractRemoteTestNG.java:115)
at org.testng.remote.RemoteTestNG.initAndRun(RemoteTestNG.java:251)
at org.testng.remote.RemoteTestNG.main(RemoteTestNG.java:77)
]]>
            </full-stacktrace>
          </exception> <!-- java.lang.AssertionError -->
          <reporter-output>
          </reporter-output>
        </test-method> <!-- TC009_verify_Valid_Login_Credential_Scenario -->
        <test-method signature="TC009_verify_Valid_Login_Credential_Scenario(java.lang.String, java.lang.String)[pri:0, instance:com.tests.LoginPageTest@1a20270e]" started-at="2022-08-02T14:00:43Z" name="TC009_verify_Valid_Login_Credential_Scenario" data-provider="setData" finished-at="2022-08-02T14:00:44Z" duration-ms="358" status="FAIL">
          <params>
            <param index="0">
              <value>
                <![CDATA[kiran@gmail.com]]>
              </value>
            </param>
            <param index="1">
              <value>
                <![CDATA[]]>
              </value>
            </param>
          </params>
          <exception class="java.lang.AssertionError">
            <message>
              <![CDATA[expected [true] but found [false]]]>
            </message>
            <full-stacktrace>
              <![CDATA[java.lang.AssertionError: expected [true] but found [false]
at org.testng.Assert.fail(Assert.java:96)
at org.testng.Assert.failNotEquals(Assert.java:776)
at org.testng.Assert.assertTrue(Assert.java:44)
at org.testng.Assert.assertTrue(Assert.java:54)
at com.tests.LoginPageTest.TC009_verify_Valid_Login_Credential_Scenario(LoginPageTest.java:93)
at java.base/jdk.internal.reflect.NativeMethodAccessorImpl.invoke0(Native Method)
at java.base/jdk.internal.reflect.NativeMethodAccessorImpl.invoke(NativeMethodAccessorImpl.java:62)
at java.base/jdk.internal.reflect.DelegatingMethodAccessorImpl.invoke(DelegatingMethodAccessorImpl.java:43)
at java.base/java.lang.reflect.Method.invoke(Method.java:566)
at org.testng.internal.MethodInvocationHelper.invokeMethod(MethodInvocationHelper.java:124)
at org.testng.internal.Invoker.invokeMethod(Invoker.java:583)
at org.testng.internal.Invoker.invokeTestMethod(Invoker.java:719)
at org.testng.internal.Invoker.invokeTestMethods(Invoker.java:989)
at org.testng.internal.TestMethodWorker.invokeTestMethods(TestMethodWorker.java:125)
at org.testng.internal.TestMethodWorker.run(TestMethodWorker.java:109)
at org.testng.TestRunner.privateRun(TestRunner.java:648)
at org.testng.TestRunner.run(TestRunner.java:505)
at org.testng.SuiteRunner.runTest(SuiteRunner.java:455)
at org.testng.SuiteRunner.runSequentially(SuiteRunner.java:450)
at org.testng.SuiteRunner.privateRun(SuiteRunner.java:415)
at org.testng.SuiteRunner.run(SuiteRunner.java:364)
at org.testng.SuiteRunnerWorker.runSuite(SuiteRunnerWorker.java:52)
at org.testng.SuiteRunnerWorker.run(SuiteRunnerWorker.java:84)
at org.testng.TestNG.runSuitesSequentially(TestNG.java:1208)
at org.testng.TestNG.runSuitesLocally(TestNG.java:1137)
at org.testng.TestNG.runSuites(TestNG.java:1049)
at org.testng.TestNG.run(TestNG.java:1017)
at org.testng.remote.AbstractRemoteTestNG.run(AbstractRemoteTestNG.java:115)
at org.testng.remote.RemoteTestNG.initAndRun(RemoteTestNG.java:251)
at org.testng.remote.RemoteTestNG.main(RemoteTestNG.java:77)
]]>
            </full-stacktrace>
          </exception> <!-- java.lang.AssertionError -->
          <reporter-output>
          </reporter-output>
        </test-method> <!-- TC009_verify_Valid_Login_Credential_Scenario -->
        <test-method signature="TC009_verify_Valid_Login_Credential_Scenario(java.lang.String, java.lang.String)[pri:0, instance:com.tests.LoginPageTest@1a20270e]" started-at="2022-08-02T14:00:44Z" name="TC009_verify_Valid_Login_Credential_Scenario" data-provider="setData" finished-at="2022-08-02T14:00:44Z" duration-ms="340" status="FAIL">
          <params>
            <param index="0">
              <value>
                <![CDATA[kiran@gmail.com]]>
              </value>
            </param>
            <param index="1">
              <value>
                <![CDATA[]]>
              </value>
            </param>
          </params>
          <exception class="java.lang.AssertionError">
            <message>
              <![CDATA[expected [true] but found [false]]]>
            </message>
            <full-stacktrace>
              <![CDATA[java.lang.AssertionError: expected [true] but found [false]
at org.testng.Assert.fail(Assert.java:96)
at org.testng.Assert.failNotEquals(Assert.java:776)
at org.testng.Assert.assertTrue(Assert.java:44)
at org.testng.Assert.assertTrue(Assert.java:54)
at com.tests.LoginPageTest.TC009_verify_Valid_Login_Credential_Scenario(LoginPageTest.java:93)
at java.base/jdk.internal.reflect.NativeMethodAccessorImpl.invoke0(Native Method)
at java.base/jdk.internal.reflect.NativeMethodAccessorImpl.invoke(NativeMethodAccessorImpl.java:62)
at java.base/jdk.internal.reflect.DelegatingMethodAccessorImpl.invoke(DelegatingMethodAccessorImpl.java:43)
at java.base/java.lang.reflect.Method.invoke(Method.java:566)
at org.testng.internal.MethodInvocationHelper.invokeMethod(MethodInvocationHelper.java:124)
at org.testng.internal.Invoker.invokeMethod(Invoker.java:583)
at org.testng.internal.Invoker.retryFailed(Invoker.java:839)
at org.testng.internal.Invoker.invokeTestMethods(Invoker.java:1010)
at org.testng.internal.TestMethodWorker.invokeTestMethods(TestMethodWorker.java:125)
at org.testng.internal.TestMethodWorker.run(TestMethodWorker.java:109)
at org.testng.TestRunner.privateRun(TestRunner.java:648)
at org.testng.TestRunner.run(TestRunner.java:505)
at org.testng.SuiteRunner.runTest(SuiteRunner.java:455)
at org.testng.SuiteRunner.runSequentially(SuiteRunner.java:450)
at org.testng.SuiteRunner.privateRun(SuiteRunner.java:415)
at org.testng.SuiteRunner.run(SuiteRunner.java:364)
at org.testng.SuiteRunnerWorker.runSuite(SuiteRunnerWorker.java:52)
at org.testng.SuiteRunnerWorker.run(SuiteRunnerWorker.java:84)
at org.testng.TestNG.runSuitesSequentially(TestNG.java:1208)
at org.testng.TestNG.runSuitesLocally(TestNG.java:1137)
at org.testng.TestNG.runSuites(TestNG.java:1049)
at org.testng.TestNG.run(TestNG.java:1017)
at org.testng.remote.AbstractRemoteTestNG.run(AbstractRemoteTestNG.java:115)
at org.testng.remote.RemoteTestNG.initAndRun(RemoteTestNG.java:251)
at org.testng.remote.RemoteTestNG.main(RemoteTestNG.java:77)
]]>
            </full-stacktrace>
          </exception> <!-- java.lang.AssertionError -->
          <reporter-output>
          </reporter-output>
        </test-method> <!-- TC009_verify_Valid_Login_Credential_Scenario -->
        <test-method signature="TC009_verify_Valid_Login_Credential_Scenario(java.lang.String, java.lang.String)[pri:0, instance:com.tests.LoginPageTest@1a20270e]" started-at="2022-08-02T14:00:44Z" name="TC009_verify_Valid_Login_Credential_Scenario" data-provider="setData" finished-at="2022-08-02T14:00:45Z" duration-ms="355" status="FAIL">
          <params>
            <param index="0">
              <value>
                <![CDATA[]]>
              </value>
            </param>
            <param index="1">
              <value>
                <![CDATA[123456]]>
              </value>
            </param>
          </params>
          <exception class="java.lang.AssertionError">
            <message>
              <![CDATA[expected [true] but found [false]]]>
            </message>
            <full-stacktrace>
              <![CDATA[java.lang.AssertionError: expected [true] but found [false]
at org.testng.Assert.fail(Assert.java:96)
at org.testng.Assert.failNotEquals(Assert.java:776)
at org.testng.Assert.assertTrue(Assert.java:44)
at org.testng.Assert.assertTrue(Assert.java:54)
at com.tests.LoginPageTest.TC009_verify_Valid_Login_Credential_Scenario(LoginPageTest.java:93)
at java.base/jdk.internal.reflect.NativeMethodAccessorImpl.invoke0(Native Method)
at java.base/jdk.internal.reflect.NativeMethodAccessorImpl.invoke(NativeMethodAccessorImpl.java:62)
at java.base/jdk.internal.reflect.DelegatingMethodAccessorImpl.invoke(DelegatingMethodAccessorImpl.java:43)
at java.base/java.lang.reflect.Method.invoke(Method.java:566)
at org.testng.internal.MethodInvocationHelper.invokeMethod(MethodInvocationHelper.java:124)
at org.testng.internal.Invoker.invokeMethod(Invoker.java:583)
at org.testng.internal.Invoker.invokeTestMethod(Invoker.java:719)
at org.testng.internal.Invoker.invokeTestMethods(Invoker.java:989)
at org.testng.internal.TestMethodWorker.invokeTestMethods(TestMethodWorker.java:125)
at org.testng.internal.TestMethodWorker.run(TestMethodWorker.java:109)
at org.testng.TestRunner.privateRun(TestRunner.java:648)
at org.testng.TestRunner.run(TestRunner.java:505)
at org.testng.SuiteRunner.runTest(SuiteRunner.java:455)
at org.testng.SuiteRunner.runSequentially(SuiteRunner.java:450)
at org.testng.SuiteRunner.privateRun(SuiteRunner.java:415)
at org.testng.SuiteRunner.run(SuiteRunner.java:364)
at org.testng.SuiteRunnerWorker.runSuite(SuiteRunnerWorker.java:52)
at org.testng.SuiteRunnerWorker.run(SuiteRunnerWorker.java:84)
at org.testng.TestNG.runSuitesSequentially(TestNG.java:1208)
at org.testng.TestNG.runSuitesLocally(TestNG.java:1137)
at org.testng.TestNG.runSuites(TestNG.java:1049)
at org.testng.TestNG.run(TestNG.java:1017)
at org.testng.remote.AbstractRemoteTestNG.run(AbstractRemoteTestNG.java:115)
at org.testng.remote.RemoteTestNG.initAndRun(RemoteTestNG.java:251)
at org.testng.remote.RemoteTestNG.main(RemoteTestNG.java:77)
]]>
            </full-stacktrace>
          </exception> <!-- java.lang.AssertionError -->
          <reporter-output>
          </reporter-output>
        </test-method> <!-- TC009_verify_Valid_Login_Credential_Scenario -->
        <test-method signature="TC009_verify_Valid_Login_Credential_Scenario(java.lang.String, java.lang.String)[pri:0, instance:com.tests.LoginPageTest@1a20270e]" started-at="2022-08-02T14:00:45Z" name="TC009_verify_Valid_Login_Credential_Scenario" data-provider="setData" finished-at="2022-08-02T14:00:45Z" duration-ms="314" status="FAIL">
          <params>
            <param index="0">
              <value>
                <![CDATA[]]>
              </value>
            </param>
            <param index="1">
              <value>
                <![CDATA[123456]]>
              </value>
            </param>
          </params>
          <exception class="java.lang.AssertionError">
            <message>
              <![CDATA[expected [true] but found [false]]]>
            </message>
            <full-stacktrace>
              <![CDATA[java.lang.AssertionError: expected [true] but found [false]
at org.testng.Assert.fail(Assert.java:96)
at org.testng.Assert.failNotEquals(Assert.java:776)
at org.testng.Assert.assertTrue(Assert.java:44)
at org.testng.Assert.assertTrue(Assert.java:54)
at com.tests.LoginPageTest.TC009_verify_Valid_Login_Credential_Scenario(LoginPageTest.java:93)
at java.base/jdk.internal.reflect.NativeMethodAccessorImpl.invoke0(Native Method)
at java.base/jdk.internal.reflect.NativeMethodAccessorImpl.invoke(NativeMethodAccessorImpl.java:62)
at java.base/jdk.internal.reflect.DelegatingMethodAccessorImpl.invoke(DelegatingMethodAccessorImpl.java:43)
at java.base/java.lang.reflect.Method.invoke(Method.java:566)
at org.testng.internal.MethodInvocationHelper.invokeMethod(MethodInvocationHelper.java:124)
at org.testng.internal.Invoker.invokeMethod(Invoker.java:583)
at org.testng.internal.Invoker.retryFailed(Invoker.java:839)
at org.testng.internal.Invoker.invokeTestMethods(Invoker.java:1010)
at org.testng.internal.TestMethodWorker.invokeTestMethods(TestMethodWorker.java:125)
at org.testng.internal.TestMethodWorker.run(TestMethodWorker.java:109)
at org.testng.TestRunner.privateRun(TestRunner.java:648)
at org.testng.TestRunner.run(TestRunner.java:505)
at org.testng.SuiteRunner.runTest(SuiteRunner.java:455)
at org.testng.SuiteRunner.runSequentially(SuiteRunner.java:450)
at org.testng.SuiteRunner.privateRun(SuiteRunner.java:415)
at org.testng.SuiteRunner.run(SuiteRunner.java:364)
at org.testng.SuiteRunnerWorker.runSuite(SuiteRunnerWorker.java:52)
at org.testng.SuiteRunnerWorker.run(SuiteRunnerWorker.java:84)
at org.testng.TestNG.runSuitesSequentially(TestNG.java:1208)
at org.testng.TestNG.runSuitesLocally(TestNG.java:1137)
at org.testng.TestNG.runSuites(TestNG.java:1049)
at org.testng.TestNG.run(TestNG.java:1017)
at org.testng.remote.AbstractRemoteTestNG.run(AbstractRemoteTestNG.java:115)
at org.testng.remote.RemoteTestNG.initAndRun(RemoteTestNG.java:251)
at org.testng.remote.RemoteTestNG.main(RemoteTestNG.java:77)
]]>
            </full-stacktrace>
          </exception> <!-- java.lang.AssertionError -->
          <reporter-output>
          </reporter-output>
        </test-method> <!-- TC009_verify_Valid_Login_Credential_Scenario -->
        <test-method signature="TC009_verify_Valid_Login_Credential_Scenario(java.lang.String, java.lang.String)[pri:0, instance:com.tests.LoginPageTest@1a20270e]" started-at="2022-08-02T14:00:45Z" name="TC009_verify_Valid_Login_Credential_Scenario" data-provider="setData" finished-at="2022-08-02T14:00:46Z" duration-ms="335" status="FAIL">
          <params>
            <param index="0">
              <value>
                <![CDATA[]]>
              </value>
            </param>
            <param index="1">
              <value>
                <![CDATA[]]>
              </value>
            </param>
          </params>
          <exception class="java.lang.AssertionError">
            <message>
              <![CDATA[expected [true] but found [false]]]>
            </message>
            <full-stacktrace>
              <![CDATA[java.lang.AssertionError: expected [true] but found [false]
at org.testng.Assert.fail(Assert.java:96)
at org.testng.Assert.failNotEquals(Assert.java:776)
at org.testng.Assert.assertTrue(Assert.java:44)
at org.testng.Assert.assertTrue(Assert.java:54)
at com.tests.LoginPageTest.TC009_verify_Valid_Login_Credential_Scenario(LoginPageTest.java:93)
at java.base/jdk.internal.reflect.NativeMethodAccessorImpl.invoke0(Native Method)
at java.base/jdk.internal.reflect.NativeMethodAccessorImpl.invoke(NativeMethodAccessorImpl.java:62)
at java.base/jdk.internal.reflect.DelegatingMethodAccessorImpl.invoke(DelegatingMethodAccessorImpl.java:43)
at java.base/java.lang.reflect.Method.invoke(Method.java:566)
at org.testng.internal.MethodInvocationHelper.invokeMethod(MethodInvocationHelper.java:124)
at org.testng.internal.Invoker.invokeMethod(Invoker.java:583)
at org.testng.internal.Invoker.invokeTestMethod(Invoker.java:719)
at org.testng.internal.Invoker.invokeTestMethods(Invoker.java:989)
at org.testng.internal.TestMethodWorker.invokeTestMethods(TestMethodWorker.java:125)
at org.testng.internal.TestMethodWorker.run(TestMethodWorker.java:109)
at org.testng.TestRunner.privateRun(TestRunner.java:648)
at org.testng.TestRunner.run(TestRunner.java:505)
at org.testng.SuiteRunner.runTest(SuiteRunner.java:455)
at org.testng.SuiteRunner.runSequentially(SuiteRunner.java:450)
at org.testng.SuiteRunner.privateRun(SuiteRunner.java:415)
at org.testng.SuiteRunner.run(SuiteRunner.java:364)
at org.testng.SuiteRunnerWorker.runSuite(SuiteRunnerWorker.java:52)
at org.testng.SuiteRunnerWorker.run(SuiteRunnerWorker.java:84)
at org.testng.TestNG.runSuitesSequentially(TestNG.java:1208)
at org.testng.TestNG.runSuitesLocally(TestNG.java:1137)
at org.testng.TestNG.runSuites(TestNG.java:1049)
at org.testng.TestNG.run(TestNG.java:1017)
at org.testng.remote.AbstractRemoteTestNG.run(AbstractRemoteTestNG.java:115)
at org.testng.remote.RemoteTestNG.initAndRun(RemoteTestNG.java:251)
at org.testng.remote.RemoteTestNG.main(RemoteTestNG.java:77)
]]>
            </full-stacktrace>
          </exception> <!-- java.lang.AssertionError -->
          <reporter-output>
          </reporter-output>
        </test-method> <!-- TC009_verify_Valid_Login_Credential_Scenario -->
        <test-method signature="TC009_verify_Valid_Login_Credential_Scenario(java.lang.String, java.lang.String)[pri:0, instance:com.tests.LoginPageTest@1a20270e]" started-at="2022-08-02T14:00:46Z" name="TC009_verify_Valid_Login_Credential_Scenario" data-provider="setData" finished-at="2022-08-02T14:00:46Z" duration-ms="322" status="FAIL">
          <params>
            <param index="0">
              <value>
                <![CDATA[]]>
              </value>
            </param>
            <param index="1">
              <value>
                <![CDATA[]]>
              </value>
            </param>
          </params>
          <exception class="java.lang.AssertionError">
            <message>
              <![CDATA[expected [true] but found [false]]]>
            </message>
            <full-stacktrace>
              <![CDATA[java.lang.AssertionError: expected [true] but found [false]
at org.testng.Assert.fail(Assert.java:96)
at org.testng.Assert.failNotEquals(Assert.java:776)
at org.testng.Assert.assertTrue(Assert.java:44)
at org.testng.Assert.assertTrue(Assert.java:54)
at com.tests.LoginPageTest.TC009_verify_Valid_Login_Credential_Scenario(LoginPageTest.java:93)
at java.base/jdk.internal.reflect.NativeMethodAccessorImpl.invoke0(Native Method)
at java.base/jdk.internal.reflect.NativeMethodAccessorImpl.invoke(NativeMethodAccessorImpl.java:62)
at java.base/jdk.internal.reflect.DelegatingMethodAccessorImpl.invoke(DelegatingMethodAccessorImpl.java:43)
at java.base/java.lang.reflect.Method.invoke(Method.java:566)
at org.testng.internal.MethodInvocationHelper.invokeMethod(MethodInvocationHelper.java:124)
at org.testng.internal.Invoker.invokeMethod(Invoker.java:583)
at org.testng.internal.Invoker.retryFailed(Invoker.java:839)
at org.testng.internal.Invoker.invokeTestMethods(Invoker.java:1010)
at org.testng.internal.TestMethodWorker.invokeTestMethods(TestMethodWorker.java:125)
at org.testng.internal.TestMethodWorker.run(TestMethodWorker.java:109)
at org.testng.TestRunner.privateRun(TestRunner.java:648)
at org.testng.TestRunner.run(TestRunner.java:505)
at org.testng.SuiteRunner.runTest(SuiteRunner.java:455)
at org.testng.SuiteRunner.runSequentially(SuiteRunner.java:450)
at org.testng.SuiteRunner.privateRun(SuiteRunner.java:415)
at org.testng.SuiteRunner.run(SuiteRunner.java:364)
at org.testng.SuiteRunnerWorker.runSuite(SuiteRunnerWorker.java:52)
at org.testng.SuiteRunnerWorker.run(SuiteRunnerWorker.java:84)
at org.testng.TestNG.runSuitesSequentially(TestNG.java:1208)
at org.testng.TestNG.runSuitesLocally(TestNG.java:1137)
at org.testng.TestNG.runSuites(TestNG.java:1049)
at org.testng.TestNG.run(TestNG.java:1017)
at org.testng.remote.AbstractRemoteTestNG.run(AbstractRemoteTestNG.java:115)
at org.testng.remote.RemoteTestNG.initAndRun(RemoteTestNG.java:251)
at org.testng.remote.RemoteTestNG.main(RemoteTestNG.java:77)
]]>
            </full-stacktrace>
          </exception> <!-- java.lang.AssertionError -->
          <reporter-output>
          </reporter-output>
        </test-method> <!-- TC009_verify_Valid_Login_Credential_Scenario -->
        <test-method signature="TC009_verify_Valid_Login_Credential_Scenario(java.lang.String, java.lang.String)[pri:0, instance:com.tests.LoginPageTest@1a20270e]" started-at="2022-08-02T14:00:46Z" name="TC009_verify_Valid_Login_Credential_Scenario" data-provider="setData" finished-at="2022-08-02T14:00:50Z" duration-ms="3364" status="PASS">
          <params>
            <param index="0">
              <value>
                <![CDATA[kiran@gmail.com]]>
              </value>
            </param>
            <param index="1">
              <value>
                <![CDATA[123456]]>
              </value>
            </param>
          </params>
          <reporter-output>
          </reporter-output>
        </test-method> <!-- TC009_verify_Valid_Login_Credential_Scenario -->
        <test-method is-config="true" signature="tearDown()[pri:0, instance:com.tests.LoginPageTest@1a20270e]" started-at="2022-08-02T14:00:50Z" name="tearDown" finished-at="2022-08-02T14:00:50Z" duration-ms="666" status="PASS">
          <reporter-output>
          </reporter-output>
        </test-method> <!-- tearDown -->
      </class> <!-- com.tests.LoginPageTest -->
      <class name="com.tests.DownloadsPageTest">
        <test-method is-config="true" signature="setUp()[pri:0, instance:com.tests.DownloadsPageTest@52c3cb31]" started-at="2022-08-02T14:02:51Z" name="setUp" finished-at="2022-08-02T14:02:55Z" duration-ms="3599" status="PASS">
          <reporter-output>
          </reporter-output>
        </test-method> <!-- setUp -->
        <test-method signature="TC001_verify_Downloads_Page_Table_Data()[pri:0, instance:com.tests.DownloadsPageTest@52c3cb31]" started-at="2022-08-02T14:02:55Z" name="TC001_verify_Downloads_Page_Table_Data" finished-at="2022-08-02T14:02:57Z" duration-ms="2111" status="PASS">
          <reporter-output>
          </reporter-output>
        </test-method> <!-- TC001_verify_Downloads_Page_Table_Data -->
        <test-method signature="TC002_verify_Thirty_Two_Bit_Support_Application()[pri:0, instance:com.tests.DownloadsPageTest@52c3cb31]" started-at="2022-08-02T14:02:57Z" name="TC002_verify_Thirty_Two_Bit_Support_Application" finished-at="2022-08-02T14:02:57Z" duration-ms="386" status="PASS">
          <reporter-output>
          </reporter-output>
        </test-method> <!-- TC002_verify_Thirty_Two_Bit_Support_Application -->
        <test-method signature="TC003_verify_Sixty_Four_Bit_Support_Application()[pri:0, instance:com.tests.DownloadsPageTest@52c3cb31]" started-at="2022-08-02T14:02:57Z" name="TC003_verify_Sixty_Four_Bit_Support_Application" finished-at="2022-08-02T14:02:58Z" duration-ms="364" status="PASS">
          <reporter-output>
          </reporter-output>
        </test-method> <!-- TC003_verify_Sixty_Four_Bit_Support_Application -->
        <test-method signature="TC004_verify_Version_Of_Application()[pri:0, instance:com.tests.DownloadsPageTest@52c3cb31]" started-at="2022-08-02T14:02:58Z" name="TC004_verify_Version_Of_Application" finished-at="2022-08-02T14:02:58Z" duration-ms="380" status="PASS">
          <reporter-output>
          </reporter-output>
        </test-method> <!-- TC004_verify_Version_Of_Application -->
        <test-method signature="TC005_verify_Official_SourceLink_Of_Perticular_Application()[pri:0, instance:com.tests.DownloadsPageTest@52c3cb31]" started-at="2022-08-02T14:02:58Z" name="TC005_verify_Official_SourceLink_Of_Perticular_Application" finished-at="2022-08-02T14:03:45Z" duration-ms="46574" status="PASS">
          <reporter-output>
          </reporter-output>
        </test-method> <!-- TC005_verify_Official_SourceLink_Of_Perticular_Application -->
        <test-method signature="TC006_verify_Logout_Page_Link_Functionality()[pri:0, instance:com.tests.DownloadsPageTest@52c3cb31]" started-at="2022-08-02T14:03:45Z" name="TC006_verify_Logout_Page_Link_Functionality" finished-at="2022-08-02T14:03:48Z" duration-ms="3361" status="PASS">
          <reporter-output>
          </reporter-output>
        </test-method> <!-- TC006_verify_Logout_Page_Link_Functionality -->
        <test-method is-config="true" signature="tearDown()[pri:0, instance:com.tests.DownloadsPageTest@52c3cb31]" started-at="2022-08-02T14:03:48Z" name="tearDown" finished-at="2022-08-02T14:03:49Z" duration-ms="690" status="PASS">
          <reporter-output>
          </reporter-output>
        </test-method> <!-- tearDown -->
      </class> <!-- com.tests.DownloadsPageTest -->
      <class name="com.tests.DashboardPageTest">
        <test-method is-config="true" signature="setUp()[pri:0, instance:com.tests.DashboardPageTest@336f1079]" started-at="2022-08-02T14:00:57Z" name="setUp" finished-at="2022-08-02T14:01:02Z" duration-ms="5173" status="PASS">
          <reporter-output>
          </reporter-output>
        </test-method> <!-- setUp -->
        <test-method signature="TC001_verify_CoursesName_And_Details_Of_Courses()[pri:0, instance:com.tests.DashboardPageTest@336f1079]" started-at="2022-08-02T14:01:02Z" name="TC001_verify_CoursesName_And_Details_Of_Courses" finished-at="2022-08-02T14:01:03Z" duration-ms="279" status="PASS">
          <reporter-output>
          </reporter-output>
        </test-method> <!-- TC001_verify_CoursesName_And_Details_Of_Courses -->
        <test-method signature="TC002_verify_More_Info_Links()[pri:0, instance:com.tests.DashboardPageTest@336f1079]" started-at="2022-08-02T14:01:03Z" name="TC002_verify_More_Info_Links" finished-at="2022-08-02T14:01:04Z" duration-ms="823" status="PASS">
          <reporter-output>
          </reporter-output>
        </test-method> <!-- TC002_verify_More_Info_Links -->
        <test-method signature="TC003_verify_SideMenubar_Links()[pri:0, instance:com.tests.DashboardPageTest@336f1079]" started-at="2022-08-02T14:01:04Z" name="TC003_verify_SideMenubar_Links" finished-at="2022-08-02T14:01:04Z" duration-ms="141" status="PASS">
          <reporter-output>
          </reporter-output>
        </test-method> <!-- TC003_verify_SideMenubar_Links -->
        <test-method signature="TC004_verify_Title_After_Clicking_On_SidebarMenu()[pri:0, instance:com.tests.DashboardPageTest@336f1079]" started-at="2022-08-02T14:01:04Z" name="TC004_verify_Title_After_Clicking_On_SidebarMenu" finished-at="2022-08-02T14:01:35Z" duration-ms="31438" status="PASS">
          <reporter-output>
          </reporter-output>
        </test-method> <!-- TC004_verify_Title_After_Clicking_On_SidebarMenu -->
        <test-method is-config="true" signature="tearDown()[pri:0, instance:com.tests.DashboardPageTest@336f1079]" started-at="2022-08-02T14:01:35Z" name="tearDown" finished-at="2022-08-02T14:01:36Z" duration-ms="842" status="PASS">
          <reporter-output>
          </reporter-output>
        </test-method> <!-- tearDown -->
      </class> <!-- com.tests.DashboardPageTest -->
      <class name="com.tests.UsersPageTest">
        <test-method is-config="true" signature="SetUp()[pri:0, instance:com.tests.UsersPageTest@2f16c6b3]" started-at="2022-08-02T14:01:36Z" name="SetUp" finished-at="2022-08-02T14:01:40Z" duration-ms="3903" status="PASS">
          <reporter-output>
          </reporter-output>
        </test-method> <!-- SetUp -->
        <test-method signature="TC001_verify_Users_Table_Data()[pri:0, instance:com.tests.UsersPageTest@2f16c6b3]" started-at="2022-08-02T14:01:40Z" name="TC001_verify_Users_Table_Data" finished-at="2022-08-02T14:01:40Z" duration-ms="329" status="PASS">
          <reporter-output>
          </reporter-output>
        </test-method> <!-- TC001_verify_Users_Table_Data -->
        <test-method signature="TC002_verify_Users_And_Courses_Data()[pri:0, instance:com.tests.UsersPageTest@2f16c6b3]" started-at="2022-08-02T14:01:40Z" name="TC002_verify_Users_And_Courses_Data" finished-at="2022-08-02T14:01:40Z" duration-ms="250" status="PASS">
          <reporter-output>
          </reporter-output>
        </test-method> <!-- TC002_verify_Users_And_Courses_Data -->
        <test-method signature="TC003_verify_Users_And_State()[pri:0, instance:com.tests.UsersPageTest@2f16c6b3]" started-at="2022-08-02T14:01:40Z" name="TC003_verify_Users_And_State" finished-at="2022-08-02T14:01:41Z" duration-ms="242" status="PASS">
          <reporter-output>
          </reporter-output>
        </test-method> <!-- TC003_verify_Users_And_State -->
        <test-method signature="TC004_verify_Users_Email_Address()[pri:0, instance:com.tests.UsersPageTest@2f16c6b3]" started-at="2022-08-02T14:01:41Z" name="TC004_verify_Users_Email_Address" finished-at="2022-08-02T14:01:41Z" duration-ms="238" status="SKIP">
          <exception class="java.lang.AssertionError">
            <message>
              <![CDATA[expected [true] but found [false]]]>
            </message>
            <full-stacktrace>
              <![CDATA[java.lang.AssertionError: expected [true] but found [false]
at org.testng.Assert.fail(Assert.java:96)
at org.testng.Assert.failNotEquals(Assert.java:776)
at org.testng.Assert.assertTrue(Assert.java:44)
at org.testng.Assert.assertTrue(Assert.java:54)
at com.tests.UsersPageTest.TC004_verify_Users_Email_Address(UsersPageTest.java:57)
at java.base/jdk.internal.reflect.NativeMethodAccessorImpl.invoke0(Native Method)
at java.base/jdk.internal.reflect.NativeMethodAccessorImpl.invoke(NativeMethodAccessorImpl.java:62)
at java.base/jdk.internal.reflect.DelegatingMethodAccessorImpl.invoke(DelegatingMethodAccessorImpl.java:43)
at java.base/java.lang.reflect.Method.invoke(Method.java:566)
at org.testng.internal.MethodInvocationHelper.invokeMethod(MethodInvocationHelper.java:124)
at org.testng.internal.Invoker.invokeMethod(Invoker.java:583)
at org.testng.internal.Invoker.invokeTestMethod(Invoker.java:719)
at org.testng.internal.Invoker.invokeTestMethods(Invoker.java:989)
at org.testng.internal.TestMethodWorker.invokeTestMethods(TestMethodWorker.java:125)
at org.testng.internal.TestMethodWorker.run(TestMethodWorker.java:109)
at org.testng.TestRunner.privateRun(TestRunner.java:648)
at org.testng.TestRunner.run(TestRunner.java:505)
at org.testng.SuiteRunner.runTest(SuiteRunner.java:455)
at org.testng.SuiteRunner.runSequentially(SuiteRunner.java:450)
at org.testng.SuiteRunner.privateRun(SuiteRunner.java:415)
at org.testng.SuiteRunner.run(SuiteRunner.java:364)
at org.testng.SuiteRunnerWorker.runSuite(SuiteRunnerWorker.java:52)
at org.testng.SuiteRunnerWorker.run(SuiteRunnerWorker.java:84)
at org.testng.TestNG.runSuitesSequentially(TestNG.java:1208)
at org.testng.TestNG.runSuitesLocally(TestNG.java:1137)
at org.testng.TestNG.runSuites(TestNG.java:1049)
at org.testng.TestNG.run(TestNG.java:1017)
at org.testng.remote.AbstractRemoteTestNG.run(AbstractRemoteTestNG.java:115)
at org.testng.remote.RemoteTestNG.initAndRun(RemoteTestNG.java:251)
at org.testng.remote.RemoteTestNG.main(RemoteTestNG.java:77)
]]>
            </full-stacktrace>
          </exception> <!-- java.lang.AssertionError -->
          <reporter-output>
          </reporter-output>
        </test-method> <!-- TC004_verify_Users_Email_Address -->
        <test-method signature="TC004_verify_Users_Email_Address()[pri:0, instance:com.tests.UsersPageTest@2f16c6b3]" started-at="2022-08-02T14:01:41Z" name="TC004_verify_Users_Email_Address" finished-at="2022-08-02T14:01:41Z" duration-ms="217" status="SKIP">
          <exception class="java.lang.AssertionError">
            <message>
              <![CDATA[expected [true] but found [false]]]>
            </message>
            <full-stacktrace>
              <![CDATA[java.lang.AssertionError: expected [true] but found [false]
at org.testng.Assert.fail(Assert.java:96)
at org.testng.Assert.failNotEquals(Assert.java:776)
at org.testng.Assert.assertTrue(Assert.java:44)
at org.testng.Assert.assertTrue(Assert.java:54)
at com.tests.UsersPageTest.TC004_verify_Users_Email_Address(UsersPageTest.java:57)
at java.base/jdk.internal.reflect.NativeMethodAccessorImpl.invoke0(Native Method)
at java.base/jdk.internal.reflect.NativeMethodAccessorImpl.invoke(NativeMethodAccessorImpl.java:62)
at java.base/jdk.internal.reflect.DelegatingMethodAccessorImpl.invoke(DelegatingMethodAccessorImpl.java:43)
at java.base/java.lang.reflect.Method.invoke(Method.java:566)
at org.testng.internal.MethodInvocationHelper.invokeMethod(MethodInvocationHelper.java:124)
at org.testng.internal.Invoker.invokeMethod(Invoker.java:583)
at org.testng.internal.Invoker.retryFailed(Invoker.java:839)
at org.testng.internal.Invoker.invokeTestMethods(Invoker.java:1010)
at org.testng.internal.TestMethodWorker.invokeTestMethods(TestMethodWorker.java:125)
at org.testng.internal.TestMethodWorker.run(TestMethodWorker.java:109)
at org.testng.TestRunner.privateRun(TestRunner.java:648)
at org.testng.TestRunner.run(TestRunner.java:505)
at org.testng.SuiteRunner.runTest(SuiteRunner.java:455)
at org.testng.SuiteRunner.runSequentially(SuiteRunner.java:450)
at org.testng.SuiteRunner.privateRun(SuiteRunner.java:415)
at org.testng.SuiteRunner.run(SuiteRunner.java:364)
at org.testng.SuiteRunnerWorker.runSuite(SuiteRunnerWorker.java:52)
at org.testng.SuiteRunnerWorker.run(SuiteRunnerWorker.java:84)
at org.testng.TestNG.runSuitesSequentially(TestNG.java:1208)
at org.testng.TestNG.runSuitesLocally(TestNG.java:1137)
at org.testng.TestNG.runSuites(TestNG.java:1049)
at org.testng.TestNG.run(TestNG.java:1017)
at org.testng.remote.AbstractRemoteTestNG.run(AbstractRemoteTestNG.java:115)
at org.testng.remote.RemoteTestNG.initAndRun(RemoteTestNG.java:251)
at org.testng.remote.RemoteTestNG.main(RemoteTestNG.java:77)
]]>
            </full-stacktrace>
          </exception> <!-- java.lang.AssertionError -->
          <reporter-output>
          </reporter-output>
        </test-method> <!-- TC004_verify_Users_Email_Address -->
        <test-method signature="TC004_verify_Users_Email_Address()[pri:0, instance:com.tests.UsersPageTest@2f16c6b3]" started-at="2022-08-02T14:01:41Z" name="TC004_verify_Users_Email_Address" finished-at="2022-08-02T14:01:41Z" duration-ms="238" status="FAIL">
          <exception class="java.lang.AssertionError">
            <message>
              <![CDATA[expected [true] but found [false]]]>
            </message>
            <full-stacktrace>
              <![CDATA[java.lang.AssertionError: expected [true] but found [false]
at org.testng.Assert.fail(Assert.java:96)
at org.testng.Assert.failNotEquals(Assert.java:776)
at org.testng.Assert.assertTrue(Assert.java:44)
at org.testng.Assert.assertTrue(Assert.java:54)
at com.tests.UsersPageTest.TC004_verify_Users_Email_Address(UsersPageTest.java:57)
at java.base/jdk.internal.reflect.NativeMethodAccessorImpl.invoke0(Native Method)
at java.base/jdk.internal.reflect.NativeMethodAccessorImpl.invoke(NativeMethodAccessorImpl.java:62)
at java.base/jdk.internal.reflect.DelegatingMethodAccessorImpl.invoke(DelegatingMethodAccessorImpl.java:43)
at java.base/java.lang.reflect.Method.invoke(Method.java:566)
at org.testng.internal.MethodInvocationHelper.invokeMethod(MethodInvocationHelper.java:124)
at org.testng.internal.Invoker.invokeMethod(Invoker.java:583)
at org.testng.internal.Invoker.retryFailed(Invoker.java:839)
at org.testng.internal.Invoker.invokeTestMethods(Invoker.java:1010)
at org.testng.internal.TestMethodWorker.invokeTestMethods(TestMethodWorker.java:125)
at org.testng.internal.TestMethodWorker.run(TestMethodWorker.java:109)
at org.testng.TestRunner.privateRun(TestRunner.java:648)
at org.testng.TestRunner.run(TestRunner.java:505)
at org.testng.SuiteRunner.runTest(SuiteRunner.java:455)
at org.testng.SuiteRunner.runSequentially(SuiteRunner.java:450)
at org.testng.SuiteRunner.privateRun(SuiteRunner.java:415)
at org.testng.SuiteRunner.run(SuiteRunner.java:364)
at org.testng.SuiteRunnerWorker.runSuite(SuiteRunnerWorker.java:52)
at org.testng.SuiteRunnerWorker.run(SuiteRunnerWorker.java:84)
at org.testng.TestNG.runSuitesSequentially(TestNG.java:1208)
at org.testng.TestNG.runSuitesLocally(TestNG.java:1137)
at org.testng.TestNG.runSuites(TestNG.java:1049)
at org.testng.TestNG.run(TestNG.java:1017)
at org.testng.remote.AbstractRemoteTestNG.run(AbstractRemoteTestNG.java:115)
at org.testng.remote.RemoteTestNG.initAndRun(RemoteTestNG.java:251)
at org.testng.remote.RemoteTestNG.main(RemoteTestNG.java:77)
]]>
            </full-stacktrace>
          </exception> <!-- java.lang.AssertionError -->
          <reporter-output>
          </reporter-output>
        </test-method> <!-- TC004_verify_Users_Email_Address -->
        <test-method signature="TC005_verify_Users_Gender()[pri:0, instance:com.tests.UsersPageTest@2f16c6b3]" started-at="2022-08-02T14:01:41Z" name="TC005_verify_Users_Gender" finished-at="2022-08-02T14:01:42Z" duration-ms="248" status="SKIP">
          <exception class="java.lang.AssertionError">
            <message>
              <![CDATA[expected [true] but found [false]]]>
            </message>
            <full-stacktrace>
              <![CDATA[java.lang.AssertionError: expected [true] but found [false]
at org.testng.Assert.fail(Assert.java:96)
at org.testng.Assert.failNotEquals(Assert.java:776)
at org.testng.Assert.assertTrue(Assert.java:44)
at org.testng.Assert.assertTrue(Assert.java:54)
at com.tests.UsersPageTest.TC005_verify_Users_Gender(UsersPageTest.java:64)
at java.base/jdk.internal.reflect.NativeMethodAccessorImpl.invoke0(Native Method)
at java.base/jdk.internal.reflect.NativeMethodAccessorImpl.invoke(NativeMethodAccessorImpl.java:62)
at java.base/jdk.internal.reflect.DelegatingMethodAccessorImpl.invoke(DelegatingMethodAccessorImpl.java:43)
at java.base/java.lang.reflect.Method.invoke(Method.java:566)
at org.testng.internal.MethodInvocationHelper.invokeMethod(MethodInvocationHelper.java:124)
at org.testng.internal.Invoker.invokeMethod(Invoker.java:583)
at org.testng.internal.Invoker.invokeTestMethod(Invoker.java:719)
at org.testng.internal.Invoker.invokeTestMethods(Invoker.java:989)
at org.testng.internal.TestMethodWorker.invokeTestMethods(TestMethodWorker.java:125)
at org.testng.internal.TestMethodWorker.run(TestMethodWorker.java:109)
at org.testng.TestRunner.privateRun(TestRunner.java:648)
at org.testng.TestRunner.run(TestRunner.java:505)
at org.testng.SuiteRunner.runTest(SuiteRunner.java:455)
at org.testng.SuiteRunner.runSequentially(SuiteRunner.java:450)
at org.testng.SuiteRunner.privateRun(SuiteRunner.java:415)
at org.testng.SuiteRunner.run(SuiteRunner.java:364)
at org.testng.SuiteRunnerWorker.runSuite(SuiteRunnerWorker.java:52)
at org.testng.SuiteRunnerWorker.run(SuiteRunnerWorker.java:84)
at org.testng.TestNG.runSuitesSequentially(TestNG.java:1208)
at org.testng.TestNG.runSuitesLocally(TestNG.java:1137)
at org.testng.TestNG.runSuites(TestNG.java:1049)
at org.testng.TestNG.run(TestNG.java:1017)
at org.testng.remote.AbstractRemoteTestNG.run(AbstractRemoteTestNG.java:115)
at org.testng.remote.RemoteTestNG.initAndRun(RemoteTestNG.java:251)
at org.testng.remote.RemoteTestNG.main(RemoteTestNG.java:77)
]]>
            </full-stacktrace>
          </exception> <!-- java.lang.AssertionError -->
          <reporter-output>
          </reporter-output>
        </test-method> <!-- TC005_verify_Users_Gender -->
        <test-method signature="TC005_verify_Users_Gender()[pri:0, instance:com.tests.UsersPageTest@2f16c6b3]" started-at="2022-08-02T14:01:42Z" name="TC005_verify_Users_Gender" finished-at="2022-08-02T14:01:42Z" duration-ms="226" status="SKIP">
          <exception class="java.lang.AssertionError">
            <message>
              <![CDATA[expected [true] but found [false]]]>
            </message>
            <full-stacktrace>
              <![CDATA[java.lang.AssertionError: expected [true] but found [false]
at org.testng.Assert.fail(Assert.java:96)
at org.testng.Assert.failNotEquals(Assert.java:776)
at org.testng.Assert.assertTrue(Assert.java:44)
at org.testng.Assert.assertTrue(Assert.java:54)
at com.tests.UsersPageTest.TC005_verify_Users_Gender(UsersPageTest.java:64)
at java.base/jdk.internal.reflect.NativeMethodAccessorImpl.invoke0(Native Method)
at java.base/jdk.internal.reflect.NativeMethodAccessorImpl.invoke(NativeMethodAccessorImpl.java:62)
at java.base/jdk.internal.reflect.DelegatingMethodAccessorImpl.invoke(DelegatingMethodAccessorImpl.java:43)
at java.base/java.lang.reflect.Method.invoke(Method.java:566)
at org.testng.internal.MethodInvocationHelper.invokeMethod(MethodInvocationHelper.java:124)
at org.testng.internal.Invoker.invokeMethod(Invoker.java:583)
at org.testng.internal.Invoker.retryFailed(Invoker.java:839)
at org.testng.internal.Invoker.invokeTestMethods(Invoker.java:1010)
at org.testng.internal.TestMethodWorker.invokeTestMethods(TestMethodWorker.java:125)
at org.testng.internal.TestMethodWorker.run(TestMethodWorker.java:109)
at org.testng.TestRunner.privateRun(TestRunner.java:648)
at org.testng.TestRunner.run(TestRunner.java:505)
at org.testng.SuiteRunner.runTest(SuiteRunner.java:455)
at org.testng.SuiteRunner.runSequentially(SuiteRunner.java:450)
at org.testng.SuiteRunner.privateRun(SuiteRunner.java:415)
at org.testng.SuiteRunner.run(SuiteRunner.java:364)
at org.testng.SuiteRunnerWorker.runSuite(SuiteRunnerWorker.java:52)
at org.testng.SuiteRunnerWorker.run(SuiteRunnerWorker.java:84)
at org.testng.TestNG.runSuitesSequentially(TestNG.java:1208)
at org.testng.TestNG.runSuitesLocally(TestNG.java:1137)
at org.testng.TestNG.runSuites(TestNG.java:1049)
at org.testng.TestNG.run(TestNG.java:1017)
at org.testng.remote.AbstractRemoteTestNG.run(AbstractRemoteTestNG.java:115)
at org.testng.remote.RemoteTestNG.initAndRun(RemoteTestNG.java:251)
at org.testng.remote.RemoteTestNG.main(RemoteTestNG.java:77)
]]>
            </full-stacktrace>
          </exception> <!-- java.lang.AssertionError -->
          <reporter-output>
          </reporter-output>
        </test-method> <!-- TC005_verify_Users_Gender -->
        <test-method signature="TC005_verify_Users_Gender()[pri:0, instance:com.tests.UsersPageTest@2f16c6b3]" started-at="2022-08-02T14:01:42Z" name="TC005_verify_Users_Gender" finished-at="2022-08-02T14:01:42Z" duration-ms="239" status="FAIL">
          <exception class="java.lang.AssertionError">
            <message>
              <![CDATA[expected [true] but found [false]]]>
            </message>
            <full-stacktrace>
              <![CDATA[java.lang.AssertionError: expected [true] but found [false]
at org.testng.Assert.fail(Assert.java:96)
at org.testng.Assert.failNotEquals(Assert.java:776)
at org.testng.Assert.assertTrue(Assert.java:44)
at org.testng.Assert.assertTrue(Assert.java:54)
at com.tests.UsersPageTest.TC005_verify_Users_Gender(UsersPageTest.java:64)
at java.base/jdk.internal.reflect.NativeMethodAccessorImpl.invoke0(Native Method)
at java.base/jdk.internal.reflect.NativeMethodAccessorImpl.invoke(NativeMethodAccessorImpl.java:62)
at java.base/jdk.internal.reflect.DelegatingMethodAccessorImpl.invoke(DelegatingMethodAccessorImpl.java:43)
at java.base/java.lang.reflect.Method.invoke(Method.java:566)
at org.testng.internal.MethodInvocationHelper.invokeMethod(MethodInvocationHelper.java:124)
at org.testng.internal.Invoker.invokeMethod(Invoker.java:583)
at org.testng.internal.Invoker.retryFailed(Invoker.java:839)
at org.testng.internal.Invoker.invokeTestMethods(Invoker.java:1010)
at org.testng.internal.TestMethodWorker.invokeTestMethods(TestMethodWorker.java:125)
at org.testng.internal.TestMethodWorker.run(TestMethodWorker.java:109)
at org.testng.TestRunner.privateRun(TestRunner.java:648)
at org.testng.TestRunner.run(TestRunner.java:505)
at org.testng.SuiteRunner.runTest(SuiteRunner.java:455)
at org.testng.SuiteRunner.runSequentially(SuiteRunner.java:450)
at org.testng.SuiteRunner.privateRun(SuiteRunner.java:415)
at org.testng.SuiteRunner.run(SuiteRunner.java:364)
at org.testng.SuiteRunnerWorker.runSuite(SuiteRunnerWorker.java:52)
at org.testng.SuiteRunnerWorker.run(SuiteRunnerWorker.java:84)
at org.testng.TestNG.runSuitesSequentially(TestNG.java:1208)
at org.testng.TestNG.runSuitesLocally(TestNG.java:1137)
at org.testng.TestNG.runSuites(TestNG.java:1049)
at org.testng.TestNG.run(TestNG.java:1017)
at org.testng.remote.AbstractRemoteTestNG.run(AbstractRemoteTestNG.java:115)
at org.testng.remote.RemoteTestNG.initAndRun(RemoteTestNG.java:251)
at org.testng.remote.RemoteTestNG.main(RemoteTestNG.java:77)
]]>
            </full-stacktrace>
          </exception> <!-- java.lang.AssertionError -->
          <reporter-output>
          </reporter-output>
        </test-method> <!-- TC005_verify_Users_Gender -->
        <test-method signature="TC006_verify_Users_MobileNumber()[pri:0, instance:com.tests.UsersPageTest@2f16c6b3]" started-at="2022-08-02T14:01:42Z" name="TC006_verify_Users_MobileNumber" finished-at="2022-08-02T14:01:43Z" duration-ms="398" status="SKIP">
          <exception class="java.lang.AssertionError">
            <message>
              <![CDATA[expected [true] but found [false]]]>
            </message>
            <full-stacktrace>
              <![CDATA[java.lang.AssertionError: expected [true] but found [false]
at org.testng.Assert.fail(Assert.java:96)
at org.testng.Assert.failNotEquals(Assert.java:776)
at org.testng.Assert.assertTrue(Assert.java:44)
at org.testng.Assert.assertTrue(Assert.java:54)
at com.tests.UsersPageTest.TC006_verify_Users_MobileNumber(UsersPageTest.java:71)
at java.base/jdk.internal.reflect.NativeMethodAccessorImpl.invoke0(Native Method)
at java.base/jdk.internal.reflect.NativeMethodAccessorImpl.invoke(NativeMethodAccessorImpl.java:62)
at java.base/jdk.internal.reflect.DelegatingMethodAccessorImpl.invoke(DelegatingMethodAccessorImpl.java:43)
at java.base/java.lang.reflect.Method.invoke(Method.java:566)
at org.testng.internal.MethodInvocationHelper.invokeMethod(MethodInvocationHelper.java:124)
at org.testng.internal.Invoker.invokeMethod(Invoker.java:583)
at org.testng.internal.Invoker.invokeTestMethod(Invoker.java:719)
at org.testng.internal.Invoker.invokeTestMethods(Invoker.java:989)
at org.testng.internal.TestMethodWorker.invokeTestMethods(TestMethodWorker.java:125)
at org.testng.internal.TestMethodWorker.run(TestMethodWorker.java:109)
at org.testng.TestRunner.privateRun(TestRunner.java:648)
at org.testng.TestRunner.run(TestRunner.java:505)
at org.testng.SuiteRunner.runTest(SuiteRunner.java:455)
at org.testng.SuiteRunner.runSequentially(SuiteRunner.java:450)
at org.testng.SuiteRunner.privateRun(SuiteRunner.java:415)
at org.testng.SuiteRunner.run(SuiteRunner.java:364)
at org.testng.SuiteRunnerWorker.runSuite(SuiteRunnerWorker.java:52)
at org.testng.SuiteRunnerWorker.run(SuiteRunnerWorker.java:84)
at org.testng.TestNG.runSuitesSequentially(TestNG.java:1208)
at org.testng.TestNG.runSuitesLocally(TestNG.java:1137)
at org.testng.TestNG.runSuites(TestNG.java:1049)
at org.testng.TestNG.run(TestNG.java:1017)
at org.testng.remote.AbstractRemoteTestNG.run(AbstractRemoteTestNG.java:115)
at org.testng.remote.RemoteTestNG.initAndRun(RemoteTestNG.java:251)
at org.testng.remote.RemoteTestNG.main(RemoteTestNG.java:77)
]]>
            </full-stacktrace>
          </exception> <!-- java.lang.AssertionError -->
          <reporter-output>
          </reporter-output>
        </test-method> <!-- TC006_verify_Users_MobileNumber -->
        <test-method signature="TC006_verify_Users_MobileNumber()[pri:0, instance:com.tests.UsersPageTest@2f16c6b3]" started-at="2022-08-02T14:01:43Z" name="TC006_verify_Users_MobileNumber" finished-at="2022-08-02T14:01:43Z" duration-ms="304" status="SKIP">
          <exception class="java.lang.AssertionError">
            <message>
              <![CDATA[expected [true] but found [false]]]>
            </message>
            <full-stacktrace>
              <![CDATA[java.lang.AssertionError: expected [true] but found [false]
at org.testng.Assert.fail(Assert.java:96)
at org.testng.Assert.failNotEquals(Assert.java:776)
at org.testng.Assert.assertTrue(Assert.java:44)
at org.testng.Assert.assertTrue(Assert.java:54)
at com.tests.UsersPageTest.TC006_verify_Users_MobileNumber(UsersPageTest.java:71)
at java.base/jdk.internal.reflect.NativeMethodAccessorImpl.invoke0(Native Method)
at java.base/jdk.internal.reflect.NativeMethodAccessorImpl.invoke(NativeMethodAccessorImpl.java:62)
at java.base/jdk.internal.reflect.DelegatingMethodAccessorImpl.invoke(DelegatingMethodAccessorImpl.java:43)
at java.base/java.lang.reflect.Method.invoke(Method.java:566)
at org.testng.internal.MethodInvocationHelper.invokeMethod(MethodInvocationHelper.java:124)
at org.testng.internal.Invoker.invokeMethod(Invoker.java:583)
at org.testng.internal.Invoker.retryFailed(Invoker.java:839)
at org.testng.internal.Invoker.invokeTestMethods(Invoker.java:1010)
at org.testng.internal.TestMethodWorker.invokeTestMethods(TestMethodWorker.java:125)
at org.testng.internal.TestMethodWorker.run(TestMethodWorker.java:109)
at org.testng.TestRunner.privateRun(TestRunner.java:648)
at org.testng.TestRunner.run(TestRunner.java:505)
at org.testng.SuiteRunner.runTest(SuiteRunner.java:455)
at org.testng.SuiteRunner.runSequentially(SuiteRunner.java:450)
at org.testng.SuiteRunner.privateRun(SuiteRunner.java:415)
at org.testng.SuiteRunner.run(SuiteRunner.java:364)
at org.testng.SuiteRunnerWorker.runSuite(SuiteRunnerWorker.java:52)
at org.testng.SuiteRunnerWorker.run(SuiteRunnerWorker.java:84)
at org.testng.TestNG.runSuitesSequentially(TestNG.java:1208)
at org.testng.TestNG.runSuitesLocally(TestNG.java:1137)
at org.testng.TestNG.runSuites(TestNG.java:1049)
at org.testng.TestNG.run(TestNG.java:1017)
at org.testng.remote.AbstractRemoteTestNG.run(AbstractRemoteTestNG.java:115)
at org.testng.remote.RemoteTestNG.initAndRun(RemoteTestNG.java:251)
at org.testng.remote.RemoteTestNG.main(RemoteTestNG.java:77)
]]>
            </full-stacktrace>
          </exception> <!-- java.lang.AssertionError -->
          <reporter-output>
          </reporter-output>
        </test-method> <!-- TC006_verify_Users_MobileNumber -->
        <test-method signature="TC006_verify_Users_MobileNumber()[pri:0, instance:com.tests.UsersPageTest@2f16c6b3]" started-at="2022-08-02T14:01:43Z" name="TC006_verify_Users_MobileNumber" finished-at="2022-08-02T14:01:43Z" duration-ms="307" status="FAIL">
          <exception class="java.lang.AssertionError">
            <message>
              <![CDATA[expected [true] but found [false]]]>
            </message>
            <full-stacktrace>
              <![CDATA[java.lang.AssertionError: expected [true] but found [false]
at org.testng.Assert.fail(Assert.java:96)
at org.testng.Assert.failNotEquals(Assert.java:776)
at org.testng.Assert.assertTrue(Assert.java:44)
at org.testng.Assert.assertTrue(Assert.java:54)
at com.tests.UsersPageTest.TC006_verify_Users_MobileNumber(UsersPageTest.java:71)
at java.base/jdk.internal.reflect.NativeMethodAccessorImpl.invoke0(Native Method)
at java.base/jdk.internal.reflect.NativeMethodAccessorImpl.invoke(NativeMethodAccessorImpl.java:62)
at java.base/jdk.internal.reflect.DelegatingMethodAccessorImpl.invoke(DelegatingMethodAccessorImpl.java:43)
at java.base/java.lang.reflect.Method.invoke(Method.java:566)
at org.testng.internal.MethodInvocationHelper.invokeMethod(MethodInvocationHelper.java:124)
at org.testng.internal.Invoker.invokeMethod(Invoker.java:583)
at org.testng.internal.Invoker.retryFailed(Invoker.java:839)
at org.testng.internal.Invoker.invokeTestMethods(Invoker.java:1010)
at org.testng.internal.TestMethodWorker.invokeTestMethods(TestMethodWorker.java:125)
at org.testng.internal.TestMethodWorker.run(TestMethodWorker.java:109)
at org.testng.TestRunner.privateRun(TestRunner.java:648)
at org.testng.TestRunner.run(TestRunner.java:505)
at org.testng.SuiteRunner.runTest(SuiteRunner.java:455)
at org.testng.SuiteRunner.runSequentially(SuiteRunner.java:450)
at org.testng.SuiteRunner.privateRun(SuiteRunner.java:415)
at org.testng.SuiteRunner.run(SuiteRunner.java:364)
at org.testng.SuiteRunnerWorker.runSuite(SuiteRunnerWorker.java:52)
at org.testng.SuiteRunnerWorker.run(SuiteRunnerWorker.java:84)
at org.testng.TestNG.runSuitesSequentially(TestNG.java:1208)
at org.testng.TestNG.runSuitesLocally(TestNG.java:1137)
at org.testng.TestNG.runSuites(TestNG.java:1049)
at org.testng.TestNG.run(TestNG.java:1017)
at org.testng.remote.AbstractRemoteTestNG.run(AbstractRemoteTestNG.java:115)
at org.testng.remote.RemoteTestNG.initAndRun(RemoteTestNG.java:251)
at org.testng.remote.RemoteTestNG.main(RemoteTestNG.java:77)
]]>
            </full-stacktrace>
          </exception> <!-- java.lang.AssertionError -->
          <reporter-output>
          </reporter-output>
        </test-method> <!-- TC006_verify_Users_MobileNumber -->
        <test-method signature="TC007_verify_Users_Can_Be_Deleted()[pri:0, instance:com.tests.UsersPageTest@2f16c6b3]" started-at="2022-08-02T14:01:43Z" name="TC007_verify_Users_Can_Be_Deleted" finished-at="2022-08-02T14:01:44Z" duration-ms="531" status="PASS">
          <reporter-output>
          </reporter-output>
        </test-method> <!-- TC007_verify_Users_Can_Be_Deleted -->
        <test-method signature="TC008_verify_Add_New_User_Functionality()[pri:0, instance:com.tests.UsersPageTest@2f16c6b3]" started-at="2022-08-02T14:01:44Z" name="TC008_verify_Add_New_User_Functionality" finished-at="2022-08-02T14:01:45Z" duration-ms="1447" status="PASS">
          <reporter-output>
          </reporter-output>
        </test-method> <!-- TC008_verify_Add_New_User_Functionality -->
        <test-method is-config="true" signature="tearDown()[pri:0, instance:com.tests.UsersPageTest@2f16c6b3]" started-at="2022-08-02T14:01:45Z" name="tearDown" finished-at="2022-08-02T14:01:46Z" duration-ms="651" status="PASS">
          <reporter-output>
          </reporter-output>
        </test-method> <!-- tearDown -->
      </class> <!-- com.tests.UsersPageTest -->
      <class name="com.tests.RegistrationPageTest">
        <test-method is-config="true" signature="SetUp()[pri:0, instance:com.tests.RegistrationPageTest@6b88ca8c]" started-at="2022-08-02T14:00:50Z" name="SetUp" finished-at="2022-08-02T14:00:53Z" duration-ms="2910" status="PASS">
          <reporter-output>
          </reporter-output>
        </test-method> <!-- SetUp -->
        <test-method signature="TC001_verify_New_User_Registration_Functionality()[pri:0, instance:com.tests.RegistrationPageTest@6b88ca8c]" started-at="2022-08-02T14:00:53Z" name="TC001_verify_New_User_Registration_Functionality" finished-at="2022-08-02T14:00:54Z" duration-ms="652" status="PASS">
          <reporter-output>
          </reporter-output>
        </test-method> <!-- TC001_verify_New_User_Registration_Functionality -->
        <test-method signature="TC002_erify_Already_User_Link_Is_Clickable()[pri:0, instance:com.tests.RegistrationPageTest@6b88ca8c]" started-at="2022-08-02T14:00:54Z" name="TC002_erify_Already_User_Link_Is_Clickable" finished-at="2022-08-02T14:00:54Z" duration-ms="323" status="PASS">
          <reporter-output>
          </reporter-output>
        </test-method> <!-- TC002_erify_Already_User_Link_Is_Clickable -->
        <test-method signature="TC003_verify_Blank_UserName_Error_Message()[pri:0, instance:com.tests.RegistrationPageTest@6b88ca8c]" started-at="2022-08-02T14:00:54Z" name="TC003_verify_Blank_UserName_Error_Message" finished-at="2022-08-02T14:00:55Z" duration-ms="610" status="PASS">
          <reporter-output>
          </reporter-output>
        </test-method> <!-- TC003_verify_Blank_UserName_Error_Message -->
        <test-method signature="TC004_verify_Blank_MobileNumber_Error_Message()[pri:0, instance:com.tests.RegistrationPageTest@6b88ca8c]" started-at="2022-08-02T14:00:55Z" name="TC004_verify_Blank_MobileNumber_Error_Message" finished-at="2022-08-02T14:00:55Z" duration-ms="623" status="PASS">
          <reporter-output>
          </reporter-output>
        </test-method> <!-- TC004_verify_Blank_MobileNumber_Error_Message -->
        <test-method signature="TC005_verify_Blank_Email_Error_Message()[pri:0, instance:com.tests.RegistrationPageTest@6b88ca8c]" started-at="2022-08-02T14:00:55Z" name="TC005_verify_Blank_Email_Error_Message" finished-at="2022-08-02T14:00:56Z" duration-ms="598" status="PASS">
          <reporter-output>
          </reporter-output>
        </test-method> <!-- TC005_verify_Blank_Email_Error_Message -->
        <test-method signature="TC006_verify_Blank_Password_Error_Message()[pri:0, instance:com.tests.RegistrationPageTest@6b88ca8c]" started-at="2022-08-02T14:00:56Z" name="TC006_verify_Blank_Password_Error_Message" finished-at="2022-08-02T14:00:57Z" duration-ms="612" status="PASS">
          <reporter-output>
          </reporter-output>
        </test-method> <!-- TC006_verify_Blank_Password_Error_Message -->
        <test-method is-config="true" signature="tearDown()[pri:0, instance:com.tests.RegistrationPageTest@6b88ca8c]" started-at="2022-08-02T14:00:57Z" name="tearDown" finished-at="2022-08-02T14:00:57Z" duration-ms="655" status="PASS">
          <reporter-output>
          </reporter-output>
        </test-method> <!-- tearDown -->
      </class> <!-- com.tests.RegistrationPageTest -->
      <class name="com.tests.OperatorsPageTest">
        <test-method is-config="true" signature="setUp()[pri:0, instance:com.tests.OperatorsPageTest@34158c08]" started-at="2022-08-02T14:01:46Z" name="setUp" finished-at="2022-08-02T14:01:50Z" duration-ms="3419" status="PASS">
          <reporter-output>
          </reporter-output>
        </test-method> <!-- setUp -->
        <test-method signature="TC001_verify_Operators_List_Table_Data()[pri:0, instance:com.tests.OperatorsPageTest@34158c08]" started-at="2022-08-02T14:01:50Z" name="TC001_verify_Operators_List_Table_Data" finished-at="2022-08-02T14:01:51Z" duration-ms="1231" status="PASS">
          <reporter-output>
          </reporter-output>
        </test-method> <!-- TC001_verify_Operators_List_Table_Data -->
        <test-method signature="TC002_verify_Technical_Person_In_Operators_List()[pri:0, instance:com.tests.OperatorsPageTest@34158c08]" started-at="2022-08-02T14:01:51Z" name="TC002_verify_Technical_Person_In_Operators_List" finished-at="2022-08-02T14:01:51Z" duration-ms="328" status="PASS">
          <reporter-output>
          </reporter-output>
        </test-method> <!-- TC002_verify_Technical_Person_In_Operators_List -->
        <test-method signature="TC003_verify_Way_To_Connect_Without_WhatsApp_Only_To_Operator()[pri:0, instance:com.tests.OperatorsPageTest@34158c08]" started-at="2022-08-02T14:01:51Z" name="TC003_verify_Way_To_Connect_Without_WhatsApp_Only_To_Operator" finished-at="2022-08-02T14:01:51Z" duration-ms="302" status="PASS">
          <reporter-output>
          </reporter-output>
        </test-method> <!-- TC003_verify_Way_To_Connect_Without_WhatsApp_Only_To_Operator -->
        <test-method signature="TC004_verify_Way_To_Connect_WhatsApp_Only_To_Operator()[pri:0, instance:com.tests.OperatorsPageTest@34158c08]" started-at="2022-08-02T14:01:51Z" name="TC004_verify_Way_To_Connect_WhatsApp_Only_To_Operator" finished-at="2022-08-02T14:01:52Z" duration-ms="309" status="PASS">
          <reporter-output>
          </reporter-output>
        </test-method> <!-- TC004_verify_Way_To_Connect_WhatsApp_Only_To_Operator -->
        <test-method signature="TC005_verify_Monday_Timing_Of_Operators()[pri:0, instance:com.tests.OperatorsPageTest@34158c08]" started-at="2022-08-02T14:01:52Z" name="TC005_verify_Monday_Timing_Of_Operators" finished-at="2022-08-02T14:01:52Z" duration-ms="288" status="PASS">
          <reporter-output>
          </reporter-output>
        </test-method> <!-- TC005_verify_Monday_Timing_Of_Operators -->
        <test-method signature="TC006_verify_Timing_Of_Operators()[pri:0, instance:com.tests.OperatorsPageTest@34158c08]" started-at="2022-08-02T14:01:52Z" name="TC006_verify_Timing_Of_Operators" finished-at="2022-08-02T14:01:52Z" duration-ms="287" status="PASS">
          <reporter-output>
          </reporter-output>
        </test-method> <!-- TC006_verify_Timing_Of_Operators -->
        <test-method signature="TC007_verify_Mobile_Number_Of_Operators()[pri:0, instance:com.tests.OperatorsPageTest@34158c08]" started-at="2022-08-02T14:01:52Z" name="TC007_verify_Mobile_Number_Of_Operators" finished-at="2022-08-02T14:01:53Z" duration-ms="275" status="PASS">
          <reporter-output>
          </reporter-output>
        </test-method> <!-- TC007_verify_Mobile_Number_Of_Operators -->
        <test-method is-config="true" signature="tearDown()[pri:0, instance:com.tests.OperatorsPageTest@34158c08]" started-at="2022-08-02T14:01:53Z" name="tearDown" finished-at="2022-08-02T14:01:53Z" duration-ms="657" status="PASS">
          <reporter-output>
          </reporter-output>
        </test-method> <!-- tearDown -->
      </class> <!-- com.tests.OperatorsPageTest -->
      <class name="com.tests.UsefulLinksPageTest">
        <test-method is-config="true" signature="SetUp()[pri:0, instance:com.tests.UsefulLinksPageTest@19e4fcac]" started-at="2022-08-02T14:01:53Z" name="SetUp" finished-at="2022-08-02T14:01:57Z" duration-ms="3805" status="PASS">
          <reporter-output>
          </reporter-output>
        </test-method> <!-- SetUp -->
        <test-method signature="TC001_verify_Useful_Links_Table_Data()[pri:0, instance:com.tests.UsefulLinksPageTest@19e4fcac]" started-at="2022-08-02T14:01:57Z" name="TC001_verify_Useful_Links_Table_Data" finished-at="2022-08-02T14:01:57Z" duration-ms="190" status="PASS">
          <reporter-output>
          </reporter-output>
        </test-method> <!-- TC001_verify_Useful_Links_Table_Data -->
        <test-method signature="TC002_verify_Content_Links_Of_Useful_Links_Page()[pri:0, instance:com.tests.UsefulLinksPageTest@19e4fcac]" started-at="2022-08-02T14:01:57Z" name="TC002_verify_Content_Links_Of_Useful_Links_Page" finished-at="2022-08-02T14:02:51Z" duration-ms="53436" status="PASS">
          <reporter-output>
          </reporter-output>
        </test-method> <!-- TC002_verify_Content_Links_Of_Useful_Links_Page -->
        <test-method is-config="true" signature="tearDown()[pri:0, instance:com.tests.UsefulLinksPageTest@19e4fcac]" started-at="2022-08-02T14:02:51Z" name="tearDown" finished-at="2022-08-02T14:02:51Z" duration-ms="653" status="PASS">
          <reporter-output>
          </reporter-output>
        </test-method> <!-- tearDown -->
      </class> <!-- com.tests.UsefulLinksPageTest -->
    </test> <!-- Test -->
  </suite> <!-- Suite -->
</testng-results>
